<sdf version='1.7'>
  <world name='default'>
    <model name='ground_plane'>
      <static>1</static>
      <link name='link'>
        <collision name='collision'>
          <geometry>
            <plane>
              <normal>0 0 1</normal>
              <size>100 100</size>
            </plane>
          </geometry>
          <surface>
            <friction>
              <ode>
                <mu>100</mu>
                <mu2>50</mu2>
              </ode>
              <torsional>
                <ode/>
              </torsional>
            </friction>
            <contact>
              <ode/>
            </contact>
            <bounce/>
          </surface>
          <max_contacts>10</max_contacts>
        </collision>
        <visual name='visual'>
          <cast_shadows>0</cast_shadows>
          <geometry>
            <plane>
              <normal>0 0 1</normal>
              <size>100 100</size>
            </plane>
          </geometry>
          <material>
            <script>
              <uri>file://media/materials/scripts/gazebo.material</uri>
              <name>Gazebo/Grey</name>
            </script>
          </material>
        </visual>
        <self_collide>0</self_collide>
        <enable_wind>0</enable_wind>
        <kinematic>0</kinematic>
      </link>
    </model>
    <light name='sun' type='directional'>
      <cast_shadows>1</cast_shadows>
      <pose>0 0 10 0 -0 0</pose>
      <diffuse>0.8 0.8 0.8 1</diffuse>
      <specular>0.2 0.2 0.2 1</specular>
      <attenuation>
        <range>1000</range>
        <constant>0.9</constant>
        <linear>0.01</linear>
        <quadratic>0.001</quadratic>
      </attenuation>
      <direction>-0.5 0.1 -0.9</direction>
      <spot>
        <inner_angle>0</inner_angle>
        <outer_angle>0</outer_angle>
        <falloff>0</falloff>
      </spot>
    </light>
    <gravity>0 0 -9.8</gravity>
    <magnetic_field>6e-06 2.3e-05 -4.2e-05</magnetic_field>
    <atmosphere type='adiabatic'/>
    <physics type='ode'>
      <max_step_size>0.001</max_step_size>
      <real_time_factor>1</real_time_factor>
      <real_time_update_rate>1000</real_time_update_rate>
    </physics>
    <scene>
      <ambient>0.4 0.4 0.4 1</ambient>
      <background>0.7 0.7 0.7 1</background>
      <shadows>1</shadows>
    </scene>
    <audio>
      <device>default</device>
    </audio>
    <wind/>
    <spherical_coordinates>
      <surface_model>EARTH_WGS84</surface_model>
      <latitude_deg>0</latitude_deg>
      <longitude_deg>0</longitude_deg>
      <elevation>0</elevation>
      <heading_deg>0</heading_deg>
    </spherical_coordinates>
    <model name='plant_1A'>
      <static>1</static>
      <link name='link'>
        <visual name='visual'>
          <geometry>
            <mesh>
              <uri>file:///home/kyshima/gazebo_ws/src/plugins/models/plants/PotPlant.dae</uri>
              <scale>0.2 0.2 0.2</scale>
            </mesh>
          </geometry>
        </visual>
        <collision name='collision'>
          <geometry>
            <mesh>
              <uri>file:///home/kyshima/gazebo_ws/src/plugins/models/plants/PotPlant.dae</uri>
              <scale>0.2 0.2 0.2</scale>
            </mesh>
          </geometry>
          <max_contacts>10</max_contacts>
          <surface>
            <contact>
              <ode/>
            </contact>
            <bounce/>
            <friction>
              <torsional>
                <ode/>
              </torsional>
              <ode/>
            </friction>
          </surface>
        </collision>
        <self_collide>0</self_collide>
        <enable_wind>0</enable_wind>
        <kinematic>0</kinematic>
      </link>
    </model>
    <model name='plant_2A'>
      <static>1</static>
      <link name='link'>
        <visual name='visual'>
          <geometry>
            <mesh>
              <uri>file:///home/kyshima/gazebo_ws/src/plugins/models/plants/PotPlant.dae</uri>
              <scale>0.2 0.2 0.2</scale>
            </mesh>
          </geometry>
        </visual>
        <collision name='collision'>
          <geometry>
            <mesh>
              <uri>file:///home/kyshima/gazebo_ws/src/plugins/models/plants/PotPlant.dae</uri>
              <scale>0.2 0.2 0.2</scale>
            </mesh>
          </geometry>
          <max_contacts>10</max_contacts>
          <surface>
            <contact>
              <ode/>
            </contact>
            <bounce/>
            <friction>
              <torsional>
                <ode/>
              </torsional>
              <ode/>
            </friction>
          </surface>
        </collision>
        <self_collide>0</self_collide>
        <enable_wind>0</enable_wind>
        <kinematic>0</kinematic>
      </link>
    </model>
    <model name='plant_3A'>
      <static>1</static>
      <link name='link'>
        <visual name='visual'>
          <geometry>
            <mesh>
              <uri>file:///home/kyshima/gazebo_ws/src/plugins/models/plants/PotPlant.dae</uri>
              <scale>0.2 0.2 0.2</scale>
            </mesh>
          </geometry>
        </visual>
        <collision name='collision'>
          <geometry>
            <mesh>
              <uri>file:///home/kyshima/gazebo_ws/src/plugins/models/plants/PotPlant.dae</uri>
              <scale>0.2 0.2 0.2</scale>
            </mesh>
          </geometry>
          <max_contacts>10</max_contacts>
          <surface>
            <contact>
              <ode/>
            </contact>
            <bounce/>
            <friction>
              <torsional>
                <ode/>
              </torsional>
              <ode/>
            </friction>
          </surface>
        </collision>
        <self_collide>0</self_collide>
        <enable_wind>0</enable_wind>
        <kinematic>0</kinematic>
      </link>
    </model>
    <model name='plant_4A'>
      <static>1</static>
      <link name='link'>
        <visual name='visual'>
          <geometry>
            <mesh>
              <uri>file:///home/kyshima/gazebo_ws/src/plugins/models/plants/PotPlant.dae</uri>
              <scale>0.2 0.2 0.2</scale>
            </mesh>
          </geometry>
        </visual>
        <collision name='collision'>
          <geometry>
            <mesh>
              <uri>file:///home/kyshima/gazebo_ws/src/plugins/models/plants/PotPlant.dae</uri>
              <scale>0.2 0.2 0.2</scale>
            </mesh>
          </geometry>
          <max_contacts>10</max_contacts>
          <surface>
            <contact>
              <ode/>
            </contact>
            <bounce/>
            <friction>
              <torsional>
                <ode/>
              </torsional>
              <ode/>
            </friction>
          </surface>
        </collision>
        <self_collide>0</self_collide>
        <enable_wind>0</enable_wind>
        <kinematic>0</kinematic>
      </link>
    </model>
    <model name='plant_1B'>
      <static>1</static>
      <link name='link'>
        <visual name='visual'>
          <geometry>
            <mesh>
              <uri>file:///home/kyshima/gazebo_ws/src/plugins/models/plants/PotPlant.dae</uri>
              <scale>0.2 0.2 0.2</scale>
            </mesh>
          </geometry>
        </visual>
        <collision name='collision'>
          <geometry>
            <mesh>
              <uri>file:///home/kyshima/gazebo_ws/src/plugins/models/plants/PotPlant.dae</uri>
              <scale>0.2 0.2 0.2</scale>
            </mesh>
          </geometry>
          <max_contacts>10</max_contacts>
          <surface>
            <contact>
              <ode/>
            </contact>
            <bounce/>
            <friction>
              <torsional>
                <ode/>
              </torsional>
              <ode/>
            </friction>
          </surface>
        </collision>
        <self_collide>0</self_collide>
        <enable_wind>0</enable_wind>
        <kinematic>0</kinematic>
      </link>
    </model>
    <model name='plant_2B'>
      <static>1</static>
      <link name='link'>
        <visual name='visual'>
          <geometry>
            <mesh>
              <uri>file:///home/kyshima/gazebo_ws/src/plugins/models/plants/PotPlant.dae</uri>
              <scale>0.2 0.2 0.2</scale>
            </mesh>
          </geometry>
        </visual>
        <collision name='collision'>
          <geometry>
            <mesh>
              <uri>file:///home/kyshima/gazebo_ws/src/plugins/models/plants/PotPlant.dae</uri>
              <scale>0.2 0.2 0.2</scale>
            </mesh>
          </geometry>
          <max_contacts>10</max_contacts>
          <surface>
            <contact>
              <ode/>
            </contact>
            <bounce/>
            <friction>
              <torsional>
                <ode/>
              </torsional>
              <ode/>
            </friction>
          </surface>
        </collision>
        <self_collide>0</self_collide>
        <enable_wind>0</enable_wind>
        <kinematic>0</kinematic>
      </link>
    </model>
    <model name='plant_3B'>
      <static>1</static>
      <link name='link'>
        <visual name='visual'>
          <geometry>
            <mesh>
              <uri>file:///home/kyshima/gazebo_ws/src/plugins/models/plants/PotPlant.dae</uri>
              <scale>0.2 0.2 0.2</scale>
            </mesh>
          </geometry>
        </visual>
        <collision name='collision'>
          <geometry>
            <mesh>
              <uri>file:///home/kyshima/gazebo_ws/src/plugins/models/plants/PotPlant.dae</uri>
              <scale>0.2 0.2 0.2</scale>
            </mesh>
          </geometry>
          <max_contacts>10</max_contacts>
          <surface>
            <contact>
              <ode/>
            </contact>
            <bounce/>
            <friction>
              <torsional>
                <ode/>
              </torsional>
              <ode/>
            </friction>
          </surface>
        </collision>
        <self_collide>0</self_collide>
        <enable_wind>0</enable_wind>
        <kinematic>0</kinematic>
      </link>
    </model>
    <model name='plant_4B'>
      <static>1</static>
      <link name='link'>
        <visual name='visual'>
          <geometry>
            <mesh>
              <uri>file:///home/kyshima/gazebo_ws/src/plugins/models/plants/PotPlant.dae</uri>
              <scale>0.2 0.2 0.2</scale>
            </mesh>
          </geometry>
        </visual>
        <collision name='collision'>
          <geometry>
            <mesh>
              <uri>file:///home/kyshima/gazebo_ws/src/plugins/models/plants/PotPlant.dae</uri>
              <scale>0.2 0.2 0.2</scale>
            </mesh>
          </geometry>
          <max_contacts>10</max_contacts>
          <surface>
            <contact>
              <ode/>
            </contact>
            <bounce/>
            <friction>
              <torsional>
                <ode/>
              </torsional>
              <ode/>
            </friction>
          </surface>
        </collision>
        <self_collide>0</self_collide>
        <enable_wind>0</enable_wind>
        <kinematic>0</kinematic>
      </link>
    </model>
    <model name='plant_1C'>
      <static>1</static>
      <link name='link'>
        <visual name='visual'>
          <geometry>
            <mesh>
              <uri>file:///home/kyshima/gazebo_ws/src/plugins/models/plants/PotPlant.dae</uri>
              <scale>0.2 0.2 0.2</scale>
            </mesh>
          </geometry>
        </visual>
        <collision name='collision'>
          <geometry>
            <mesh>
              <uri>file:///home/kyshima/gazebo_ws/src/plugins/models/plants/PotPlant.dae</uri>
              <scale>0.2 0.2 0.2</scale>
            </mesh>
          </geometry>
          <max_contacts>10</max_contacts>
          <surface>
            <contact>
              <ode/>
            </contact>
            <bounce/>
            <friction>
              <torsional>
                <ode/>
              </torsional>
              <ode/>
            </friction>
          </surface>
        </collision>
        <self_collide>0</self_collide>
        <enable_wind>0</enable_wind>
        <kinematic>0</kinematic>
      </link>
    </model>
    <model name='plant_2C'>
      <static>1</static>
      <link name='link'>
        <visual name='visual'>
          <geometry>
            <mesh>
              <uri>file:///home/kyshima/gazebo_ws/src/plugins/models/plants/PotPlant.dae</uri>
              <scale>0.2 0.2 0.2</scale>
            </mesh>
          </geometry>
        </visual>
        <collision name='collision'>
          <geometry>
            <mesh>
              <uri>file:///home/kyshima/gazebo_ws/src/plugins/models/plants/PotPlant.dae</uri>
              <scale>0.2 0.2 0.2</scale>
            </mesh>
          </geometry>
          <max_contacts>10</max_contacts>
          <surface>
            <contact>
              <ode/>
            </contact>
            <bounce/>
            <friction>
              <torsional>
                <ode/>
              </torsional>
              <ode/>
            </friction>
          </surface>
        </collision>
        <self_collide>0</self_collide>
        <enable_wind>0</enable_wind>
        <kinematic>0</kinematic>
      </link>
    </model>
    <model name='plant_3C'>
      <static>1</static>
      <link name='link'>
        <visual name='visual'>
          <geometry>
            <mesh>
              <uri>file:///home/kyshima/gazebo_ws/src/plugins/models/plants/PotPlant.dae</uri>
              <scale>0.2 0.2 0.2</scale>
            </mesh>
          </geometry>
        </visual>
        <collision name='collision'>
          <geometry>
            <mesh>
              <uri>file:///home/kyshima/gazebo_ws/src/plugins/models/plants/PotPlant.dae</uri>
              <scale>0.2 0.2 0.2</scale>
            </mesh>
          </geometry>
          <max_contacts>10</max_contacts>
          <surface>
            <contact>
              <ode/>
            </contact>
            <bounce/>
            <friction>
              <torsional>
                <ode/>
              </torsional>
              <ode/>
            </friction>
          </surface>
        </collision>
        <self_collide>0</self_collide>
        <enable_wind>0</enable_wind>
        <kinematic>0</kinematic>
      </link>
    </model>
    <model name='plant_4C'>
      <static>1</static>
      <link name='link'>
        <visual name='visual'>
          <geometry>
            <mesh>
              <uri>file:///home/kyshima/gazebo_ws/src/plugins/models/plants/PotPlant.dae</uri>
              <scale>0.2 0.2 0.2</scale>
            </mesh>
          </geometry>
        </visual>
        <collision name='collision'>
          <geometry>
            <mesh>
              <uri>file:///home/kyshima/gazebo_ws/src/plugins/models/plants/PotPlant.dae</uri>
              <scale>0.2 0.2 0.2</scale>
            </mesh>
          </geometry>
          <max_contacts>10</max_contacts>
          <surface>
            <contact>
              <ode/>
            </contact>
            <bounce/>
            <friction>
              <torsional>
                <ode/>
              </torsional>
              <ode/>
            </friction>
          </surface>
        </collision>
        <self_collide>0</self_collide>
        <enable_wind>0</enable_wind>
        <kinematic>0</kinematic>
      </link>
    </model>
    <model name='plant_1D'>
      <static>1</static>
      <link name='link'>
        <visual name='visual'>
          <geometry>
            <mesh>
              <uri>file:///home/kyshima/gazebo_ws/src/plugins/models/plants/PotPlant.dae</uri>
              <scale>0.2 0.2 0.2</scale>
            </mesh>
          </geometry>
        </visual>
        <collision name='collision'>
          <geometry>
            <mesh>
              <uri>file:///home/kyshima/gazebo_ws/src/plugins/models/plants/PotPlant.dae</uri>
              <scale>0.2 0.2 0.2</scale>
            </mesh>
          </geometry>
          <max_contacts>10</max_contacts>
          <surface>
            <contact>
              <ode/>
            </contact>
            <bounce/>
            <friction>
              <torsional>
                <ode/>
              </torsional>
              <ode/>
            </friction>
          </surface>
        </collision>
        <self_collide>0</self_collide>
        <enable_wind>0</enable_wind>
        <kinematic>0</kinematic>
      </link>
    </model>
    <model name='plant_2D'>
      <static>1</static>
      <link name='link'>
        <visual name='visual'>
          <geometry>
            <mesh>
              <uri>file:///home/kyshima/gazebo_ws/src/plugins/models/plants/PotPlant.dae</uri>
              <scale>0.2 0.2 0.2</scale>
            </mesh>
          </geometry>
        </visual>
        <collision name='collision'>
          <geometry>
            <mesh>
              <uri>file:///home/kyshima/gazebo_ws/src/plugins/models/plants/PotPlant.dae</uri>
              <scale>0.2 0.2 0.2</scale>
            </mesh>
          </geometry>
          <max_contacts>10</max_contacts>
          <surface>
            <contact>
              <ode/>
            </contact>
            <bounce/>
            <friction>
              <torsional>
                <ode/>
              </torsional>
              <ode/>
            </friction>
          </surface>
        </collision>
        <self_collide>0</self_collide>
        <enable_wind>0</enable_wind>
        <kinematic>0</kinematic>
      </link>
    </model>
    <model name='plant_3D'>
      <static>1</static>
      <link name='link'>
        <visual name='visual'>
          <geometry>
            <mesh>
              <uri>file:///home/kyshima/gazebo_ws/src/plugins/models/plants/PotPlant.dae</uri>
              <scale>0.2 0.2 0.2</scale>
            </mesh>
          </geometry>
        </visual>
        <collision name='collision'>
          <geometry>
            <mesh>
              <uri>file:///home/kyshima/gazebo_ws/src/plugins/models/plants/PotPlant.dae</uri>
              <scale>0.2 0.2 0.2</scale>
            </mesh>
          </geometry>
          <max_contacts>10</max_contacts>
          <surface>
            <contact>
              <ode/>
            </contact>
            <bounce/>
            <friction>
              <torsional>
                <ode/>
              </torsional>
              <ode/>
            </friction>
          </surface>
        </collision>
        <self_collide>0</self_collide>
        <enable_wind>0</enable_wind>
        <kinematic>0</kinematic>
      </link>
    </model>
    <model name='plant_4D'>
      <static>1</static>
      <link name='link'>
        <visual name='visual'>
          <geometry>
            <mesh>
              <uri>file:///home/kyshima/gazebo_ws/src/plugins/models/plants/PotPlant.dae</uri>
              <scale>0.2 0.2 0.2</scale>
            </mesh>
          </geometry>
        </visual>
        <collision name='collision'>
          <geometry>
            <mesh>
              <uri>file:///home/kyshima/gazebo_ws/src/plugins/models/plants/PotPlant.dae</uri>
              <scale>0.2 0.2 0.2</scale>
            </mesh>
          </geometry>
          <max_contacts>10</max_contacts>
          <surface>
            <contact>
              <ode/>
            </contact>
            <bounce/>
            <friction>
              <torsional>
                <ode/>
              </torsional>
              <ode/>
            </friction>
          </surface>
        </collision>
        <self_collide>0</self_collide>
        <enable_wind>0</enable_wind>
        <kinematic>0</kinematic>
      </link>
    </model>
    <state world_name='default'>
      <sim_time>1294 157000000</sim_time>
      <real_time>114 264716619</real_time>
      <wall_time>1718385756 448420935</wall_time>
      <iterations>110003</iterations>
      <model name='2outroBigCilindro'>
        <pose>-7.5 -6.2 0.136888 0 2e-06 -1.5e-05</pose>
        <scale>1 1 1</scale>
        <link name='link'>
          <pose>-7.5 -6.2 0.136888 0 2e-06 -1.5e-05</pose>
          <velocity>0 0 0 0 -0 0</velocity>
          <acceleration>0 0 -9.8 0 -0 0</acceleration>
          <wrench>0 0 -9.8 0 -0 0</wrench>
        </link>
      </model>
      <model name='charger'>
        <pose>-8.2 -7 0 0 0 -1.62417</pose>
        <scale>1 1 1</scale>
        <link name='link'>
          <pose>-8.2 -7 0 0 0 -1.62417</pose>
          <velocity>0 0 0 0 -0 0</velocity>
          <acceleration>0 0 0 0 -0 0</acceleration>
          <wrench>0 0 0 0 -0 0</wrench>
        </link>
      </model>
      <model name='ground_plane'>
        <pose>0 0 0 0 -0 0</pose>
        <scale>1 1 1</scale>
        <link name='link'>
          <pose>0 0 0 0 -0 0</pose>
          <velocity>0 0 0 0 -0 0</velocity>
          <acceleration>0 0 0 0 -0 0</acceleration>
          <wrench>0 0 0 0 -0 0</wrench>
        </link>
      </model>
      <model name='mud'>
        <pose>-1 0 0 0 -0 0</pose>
        <scale>1 1 1</scale>
        <link name='link'>
          <pose>-1 0 0 0 -0 0</pose>
          <velocity>0 0 0 0 -0 0</velocity>
          <acceleration>0 0 0 0 -0 0</acceleration>
          <wrench>0 0 0 0 -0 0</wrench>
        </link>
      </model>
      <model name='outroBigCilindro'>
        <pose>-8 6.2 0.136896 0 -0 -1.2e-05</pose>
        <scale>1 1 1</scale>
        <link name='link'>
          <pose>-8 6.2 0.136896 0 -0 -1.2e-05</pose>
          <velocity>0 0 0 0 -0 0</velocity>
          <acceleration>-0 -0 19.6 1e-06 -0 0</acceleration>
          <wrench>-0 -0 19.6 0 -0 0</wrench>
        </link>
      </model>
      <model name='plant_1A'>
        <pose>-2 -3 0 0 -0 0</pose>
        <scale>1 1 1</scale>
        <link name='link'>
          <pose>-2 -3 0 0 -0 0</pose>
          <velocity>0 0 0 0 -0 0</velocity>
          <acceleration>0 0 0 0 -0 0</acceleration>
          <wrench>0 0 0 0 -0 0</wrench>
        </link>
      </model>
      <model name='plant_1B'>
        <pose>-1.333 -3 0 0 -0 0</pose>
        <scale>1 1 1</scale>
        <link name='link'>
          <pose>-1.333 -3 0 0 -0 0</pose>
          <velocity>0 0 0 0 -0 0</velocity>
          <acceleration>0 0 0 0 -0 0</acceleration>
          <wrench>0 0 0 0 -0 0</wrench>
        </link>
      </model>
      <model name='plant_1C'>
        <pose>-0.667 -3 0 0 -0 0</pose>
        <scale>1 1 1</scale>
        <link name='link'>
          <pose>-0.667 -3 0 0 -0 0</pose>
          <velocity>0 0 0 0 -0 0</velocity>
          <acceleration>0 0 0 0 -0 0</acceleration>
          <wrench>0 0 0 0 -0 0</wrench>
        </link>
      </model>
      <model name='plant_1D'>
        <pose>0 -3 0 0 -0 0</pose>
        <scale>1 1 1</scale>
        <link name='link'>
          <pose>0 -3 0 0 -0 0</pose>
          <velocity>0 0 0 0 -0 0</velocity>
          <acceleration>0 0 0 0 -0 0</acceleration>
          <wrench>0 0 0 0 -0 0</wrench>
        </link>
      </model>
      <model name='plant_2A'>
        <pose>2 -3 0 0 -0 0</pose>
        <scale>1 1 1</scale>
        <link name='link'>
          <pose>2 -3 0 0 -0 0</pose>
          <velocity>0 0 0 0 -0 0</velocity>
          <acceleration>0 0 0 0 -0 0</acceleration>
          <wrench>0 0 0 0 -0 0</wrench>
        </link>
      </model>
      <model name='plant_2B'>
        <pose>2.667 -3 0 0 -0 0</pose>
        <scale>1 1 1</scale>
        <link name='link'>
          <pose>2.667 -3 0 0 -0 0</pose>
          <velocity>0 0 0 0 -0 0</velocity>
          <acceleration>0 0 0 0 -0 0</acceleration>
          <wrench>0 0 0 0 -0 0</wrench>
        </link>
      </model>
      <model name='plant_2C'>
        <pose>3.333 -3 0 0 -0 0</pose>
        <scale>1 1 1</scale>
        <link name='link'>
          <pose>3.333 -3 0 0 -0 0</pose>
          <velocity>0 0 0 0 -0 0</velocity>
          <acceleration>0 0 0 0 -0 0</acceleration>
          <wrench>0 0 0 0 -0 0</wrench>
        </link>
      </model>
      <model name='plant_2D'>
        <pose>4 -3 0 0 -0 0</pose>
        <scale>1 1 1</scale>
        <link name='link'>
          <pose>4 -3 0 0 -0 0</pose>
          <velocity>0 0 0 0 -0 0</velocity>
          <acceleration>0 0 0 0 -0 0</acceleration>
          <wrench>0 0 0 0 -0 0</wrench>
        </link>
      </model>
      <model name='plant_3A'>
        <pose>-2 3 0 0 -0 0</pose>
        <scale>1 1 1</scale>
        <link name='link'>
          <pose>-2 3 0 0 -0 0</pose>
          <velocity>0 0 0 0 -0 0</velocity>
          <acceleration>0 0 0 0 -0 0</acceleration>
          <wrench>0 0 0 0 -0 0</wrench>
        </link>
      </model>
      <model name='plant_3B'>
        <pose>-1.333 3 0 0 -0 0</pose>
        <scale>1 1 1</scale>
        <link name='link'>
          <pose>-1.333 3 0 0 -0 0</pose>
          <velocity>0 0 0 0 -0 0</velocity>
          <acceleration>0 0 0 0 -0 0</acceleration>
          <wrench>0 0 0 0 -0 0</wrench>
        </link>
      </model>
      <model name='plant_3C'>
        <pose>-0.667 3 0 0 -0 0</pose>
        <scale>1 1 1</scale>
        <link name='link'>
          <pose>-0.667 3 0 0 -0 0</pose>
          <velocity>0 0 0 0 -0 0</velocity>
          <acceleration>0 0 0 0 -0 0</acceleration>
          <wrench>0 0 0 0 -0 0</wrench>
        </link>
      </model>
      <model name='plant_3D'>
        <pose>0 3 0 0 -0 0</pose>
        <scale>1 1 1</scale>
        <link name='link'>
          <pose>0 3 0 0 -0 0</pose>
          <velocity>0 0 0 0 -0 0</velocity>
          <acceleration>0 0 0 0 -0 0</acceleration>
          <wrench>0 0 0 0 -0 0</wrench>
        </link>
      </model>
      <model name='plant_4A'>
        <pose>2 3 0 0 -0 0</pose>
        <scale>1 1 1</scale>
        <link name='link'>
          <pose>2 3 0 0 -0 0</pose>
          <velocity>0 0 0 0 -0 0</velocity>
          <acceleration>0 0 0 0 -0 0</acceleration>
          <wrench>0 0 0 0 -0 0</wrench>
        </link>
      </model>
      <model name='plant_4B'>
        <pose>2.667 3 0 0 -0 0</pose>
        <scale>1 1 1</scale>
        <link name='link'>
          <pose>2.667 3 0 0 -0 0</pose>
          <velocity>0 0 0 0 -0 0</velocity>
          <acceleration>0 0 0 0 -0 0</acceleration>
          <wrench>0 0 0 0 -0 0</wrench>
        </link>
      </model>
      <model name='plant_4C'>
        <pose>3.333 3 0 0 -0 0</pose>
        <scale>1 1 1</scale>
        <link name='link'>
          <pose>3.333 3 0 0 -0 0</pose>
          <velocity>0 0 0 0 -0 0</velocity>
          <acceleration>0 0 0 0 -0 0</acceleration>
          <wrench>0 0 0 0 -0 0</wrench>
        </link>
      </model>
      <model name='plant_4D'>
        <pose>4 3 0 0 -0 0</pose>
        <scale>1 1 1</scale>
        <link name='link'>
          <pose>4 3 0 0 -0 0</pose>
          <velocity>0 0 0 0 -0 0</velocity>
          <acceleration>0 0 0 0 -0 0</acceleration>
          <wrench>0 0 0 0 -0 0</wrench>
        </link>
      </model>
      <model name='robot1'>
        <pose>-8.49968 3.00001 0.25887 1e-06 0.007582 -3.9e-05</pose>
        <scale>1 1 1</scale>
        <link name='base_link'>
          <pose>-8.57473 3.00001 0.346941 1e-06 0.007582 -3.9e-05</pose>
          <velocity>0 0 -0 0 -0 0</velocity>
          <acceleration>0 0 0 0 -0 0</acceleration>
          <wrench>0 0 0 0 -0 0</wrench>
        </link>
        <link name='caster'>
          <pose>-8.97871 3.00003 0.2 -0.000336 -0.025141 3.7e-05</pose>
          <velocity>0 0 0 -4e-06 1e-06 0</velocity>
          <acceleration>0 -0 -0 0 -0 0</acceleration>
          <wrench>0 -0 -0 0 -0 0</wrench>
        </link>
        <link name='left_wheel'>
          <pose>-8.22263 3.31251 0.244269 -1.5707 -0.020486 -4.1e-05</pose>
          <velocity>0 0 -0 0 2e-06 0</velocity>
          <acceleration>0 -0 0 0 -0 0</acceleration>
          <wrench>0 -0 0 0 -0 0</wrench>
        </link>
        <link name='right_wheel'>
          <pose>-8.22265 2.68749 0.244268 -1.5707 -0.020767 -4.1e-05</pose>
          <velocity>-0 0 -0 0 -0 0</velocity>
          <acceleration>-0 0 -0 -0 -0 -0</acceleration>
          <wrench>-0 0 -0 0 -0 0</wrench>
        </link>
      </model>
      <model name='robot2'>
        <pose>-8.49968 1.00001 0.25887 1e-06 0.007581 -2.6e-05</pose>
        <scale>1 1 1</scale>
        <link name='base_link'>
          <pose>-8.57473 1.00001 0.346941 1e-06 0.007581 -2.6e-05</pose>
          <velocity>0 0 -0 0 -0 0</velocity>
          <acceleration>0 0 0 0 -0 0</acceleration>
          <wrench>0 0 0 0 -0 0</wrench>
        </link>
        <link name='caster'>
          <pose>-8.97871 1.00002 0.2 -0.000479 -0.025081 5.5e-05</pose>
          <velocity>0 0 0 -4e-06 1e-06 0</velocity>
          <acceleration>-0 0 -0 0 -0 0</acceleration>
          <wrench>-0 0 -0 0 -0 0</wrench>
        </link>
        <link name='left_wheel'>
          <pose>-8.22263 1.31252 0.244269 -1.5707 -0.020491 -2.9e-05</pose>
          <velocity>0 0 -0 0 2e-06 0</velocity>
          <acceleration>0 0 0 0 -0 0</acceleration>
          <wrench>0 0 0 0 -0 0</wrench>
        </link>
        <link name='right_wheel'>
          <pose>-8.22265 0.687485 0.244269 -1.5707 -0.020772 -2.9e-05</pose>
          <velocity>-0 0 -0 0 -0 0</velocity>
          <acceleration>0 -0 0 0 -0 0</acceleration>
          <wrench>0 -0 0 0 -0 0</wrench>
        </link>
      </model>
      <model name='robot3'>
        <pose>-8.49975 -0.999979 0.258897 3e-06 0.007525 -7.5e-05</pose>
        <scale>1 1 1</scale>
        <link name='base_link'>
          <pose>-8.5748 -0.999974 0.346964 3e-06 0.007525 -7.5e-05</pose>
          <velocity>0 1e-06 -0 0 0 -2e-06</velocity>
          <acceleration>0 0 0 0 -0 0</acceleration>
          <wrench>0 0 0 0 -0 0</wrench>
        </link>
        <link name='caster'>
          <pose>-8.97877 -0.999943 0.2 -0.001861 -0.040589 0.00015</pose>
          <velocity>0 2e-06 0 -1.6e-05 1e-06 0</velocity>
          <acceleration>-0 0 -0 -0 -0 -0</acceleration>
          <wrench>-0 0 -0 0 -0 0</wrench>
        </link>
        <link name='left_wheel'>
          <pose>-8.22268 -0.687486 0.244313 -1.5707 -0.026223 -7.8e-05</pose>
          <velocity>1e-06 0 0 -0 5e-06 -2e-06</velocity>
          <acceleration>0 -0 0 0 -0 0</acceleration>
          <wrench>0 -0 0 0 -0 0</wrench>
        </link>
        <link name='right_wheel'>
          <pose>-8.22273 -1.31251 0.244311 -1.5707 -0.02659 -7.8e-05</pose>
          <velocity>-1e-06 0 -0 -0 -4e-06 -2e-06</velocity>
          <acceleration>0 0 0 0 -0 0</acceleration>
          <wrench>0 0 0 0 -0 0</wrench>
        </link>
      </model>
      <model name='robot4'>
        <pose>-8.49982 -2.99998 0.259209 3e-06 0.006874 -7.2e-05</pose>
        <scale>1 1 1</scale>
        <link name='base_link'>
          <pose>-8.65004 -2.99997 0.435246 3e-06 0.006874 -7.2e-05</pose>
          <velocity>0 2e-06 0 0 -0 -4e-06</velocity>
          <acceleration>-0 0 0 0 -0 0</acceleration>
          <wrench>-0 0 0 0 -0 0</wrench>
        </link>
        <link name='caster'>
          <pose>-8.97881 -2.99994 0.2 -0.003509 -0.030644 0.000376</pose>
          <velocity>0 3e-06 0 -3e-05 3e-06 -0</velocity>
          <acceleration>0 0 -0 0 -0 0</acceleration>
          <wrench>0 0 -0 0 -0 0</wrench>
        </link>
        <link name='left_wheel'>
          <pose>-8.22275 -2.68749 0.244805 -1.5707 -0.017157 -7.5e-05</pose>
          <velocity>2e-06 0 0 0 1e-05 -4e-06</velocity>
          <acceleration>0 0 0 0 -0 0</acceleration>
          <wrench>0 0 0 0 -0 0</wrench>
        </link>
        <link name='right_wheel'>
          <pose>-8.22279 -3.31251 0.244803 -1.5707 -0.018166 -7.5e-05</pose>
          <velocity>-1e-06 0 -0 0 -6e-06 -4e-06</velocity>
          <acceleration>0 0 0 0 -0 0</acceleration>
          <wrench>0 0 0 0 -0 0</wrench>
        </link>
      </model>
      <model name='well'>
        <pose>-8 8 0 0 -0 0</pose>
        <scale>1 1 1</scale>
        <link name='link'>
          <pose>-8 8 0 0 -0 0</pose>
          <velocity>0 0 0 0 -0 0</velocity>
          <acceleration>0 0 0 0 -0 0</acceleration>
          <wrench>0 0 0 0 -0 0</wrench>
        </link>
      </model>
      <light name='sun'>
        <pose>0 0 5 0 -0 0</pose>
      </light>
      <light name='sun_clone'>
        <pose>13.3913 1.36485 5 0 -0 0</pose>
      </light>
    </state>
    <gui fullscreen='0'>
      <camera name='user_camera'>
        <pose>-22.1376 14.4642 24.2266 0 0.793848 -0.861648</pose>
        <view_controller>orbit</view_controller>
        <projection_type>perspective</projection_type>
      </camera>
    </gui>
    <model name='well'>
      <static>1</static>
      <link name='link'>
        <visual name='visual'>
          <geometry>
            <mesh>
              <uri>file:///home/kyshima/gazebo_ws/src/plugins/models/well/meshes/well.dae</uri>
              <scale>0.1 0.1 0.1</scale>
            </mesh>
          </geometry>
        </visual>
        <self_collide>0</self_collide>
        <enable_wind>0</enable_wind>
        <kinematic>0</kinematic>
      </link>
      <pose>-8.48011 6.54444 0 0 -0 0</pose>
    </model>
    <model name='mud'>
      <static>1</static>
      <link name='link'>
        <collision name='collision'>
          <geometry>
            <box>
              <size>17.6 20 0.2</size>
            </box>
          </geometry>
          <max_contacts>10</max_contacts>
          <surface>
            <contact>
              <ode/>
            </contact>
            <bounce/>
            <friction>
              <torsional>
                <ode/>
              </torsional>
              <ode/>
            </friction>
          </surface>
        </collision>
        <visual name='visual_1'>
          <pose>-4.4 5 0 0 -0 0</pose>
          <cast_shadows>0</cast_shadows>
          <geometry>
            <box>
              <size>8.8 10 0.2</size>
            </box>
          </geometry>
          <material>
            <script>
              <uri>model://mud_box/materials/scripts</uri>
              <uri>model://mud_box/materials/textures</uri>
              <name>vrc/mud</name>
            </script>
          </material>
        </visual>
        <visual name='visual_2'>
          <pose>4.4 5 0 0 -0 0</pose>
          <cast_shadows>0</cast_shadows>
          <geometry>
            <box>
              <size>8.8 10 0.2</size>
            </box>
          </geometry>
          <material>
            <script>
              <uri>model://mud_box/materials/scripts</uri>
              <uri>model://mud_box/materials/textures</uri>
              <name>vrc/mud</name>
            </script>
          </material>
        </visual>
        <visual name='visual_3'>
          <pose>4.4 -5 0 0 -0 0</pose>
          <cast_shadows>0</cast_shadows>
          <geometry>
            <box>
              <size>8.8 10 0.2</size>
            </box>
          </geometry>
          <material>
            <script>
              <uri>model://mud_box/materials/scripts</uri>
              <uri>model://mud_box/materials/textures</uri>
              <name>vrc/mud</name>
            </script>
          </material>
        </visual>
        <visual name='visual_4'>
          <pose>-4.4 -5 0 0 -0 0</pose>
          <cast_shadows>0</cast_shadows>
          <geometry>
            <box>
              <size>8.8 10 0.2</size>
            </box>
          </geometry>
          <material>
            <script>
              <uri>model://mud_box/materials/scripts</uri>
              <uri>model://mud_box/materials/textures</uri>
              <name>vrc/mud</name>
            </script>
          </material>
        </visual>
        <self_collide>0</self_collide>
        <enable_wind>0</enable_wind>
        <kinematic>0</kinematic>
      </link>
      <pose>-1.17148 -0.05098 0 0 -0 0</pose>
    </model>
    <model name='charger'>
      <static>1</static>
      <link name='link'>
        <visual name='visual'>
          <geometry>
            <mesh>
              <uri>file:///home/kyshima/gazebo_ws/src/plugins/models/charger2/charger.dae</uri>
              <scale>1 1 1</scale>
            </mesh>
          </geometry>
        </visual>
        <self_collide>0</self_collide>
        <enable_wind>0</enable_wind>
        <kinematic>0</kinematic>
      </link>
      <pose>-8.43554 -7.3173 0 0 -0 0</pose>
    </model>
    <model name='outroBigCilindro'>
      <link name='link'>
        <inertial>
          <mass>1</mass>
          <inertia>
            <ixx>0.145833</ixx>
            <ixy>0</ixy>
            <ixz>0</ixz>
            <iyy>0.145833</iyy>
            <iyz>0</iyz>
            <izz>0.125</izz>
          </inertia>
          <pose>0 0 0 0 -0 0</pose>
        </inertial>
        <self_collide>0</self_collide>
        <enable_wind>0</enable_wind>
        <kinematic>0</kinematic>
        <pose>0 0 0 0 -0 0</pose>
        <gravity>1</gravity>
        <visual name='visual'>
          <geometry>
            <cylinder>
              <radius>1.04919</radius>
              <length>0.0737919</length>
            </cylinder>
          </geometry>
          <material>
            <script>
              <name>Gazebo/Grey</name>
              <uri>file://media/materials/scripts/gazebo.material</uri>
            </script>
            <shader type='pixel'>
              <normal_map>__default__</normal_map>
            </shader>
            <ambient>0.2 0.1 0.1 1</ambient>
            <diffuse>0.2 0.1 0.1 1</diffuse>
            <specular>0.2 0.11 0.11 1</specular>
            <emissive>0.2 0.1 0.1 1</emissive>
          </material>
          <pose>0 0 0 0 -0 0</pose>
          <transparency>0</transparency>
          <cast_shadows>1</cast_shadows>
        </visual>
        <collision name='collision'>
          <laser_retro>0</laser_retro>
          <max_contacts>10</max_contacts>
          <pose>0 0 0 0 -0 0</pose>
          <geometry>
            <cylinder>
              <radius>1.04919</radius>
              <length>0.073792</length>
            </cylinder>
          </geometry>
          <surface>
            <friction>
              <ode>
                <mu>1</mu>
                <mu2>1</mu2>
                <fdir1>0 0 0</fdir1>
                <slip1>0</slip1>
                <slip2>0</slip2>
              </ode>
              <torsional>
                <coefficient>1</coefficient>
                <patch_radius>0</patch_radius>
                <surface_radius>0</surface_radius>
                <use_patch_radius>1</use_patch_radius>
                <ode>
                  <slip>0</slip>
                </ode>
              </torsional>
            </friction>
            <bounce>
              <restitution_coefficient>0</restitution_coefficient>
              <threshold>1e+06</threshold>
            </bounce>
            <contact>
              <collide_without_contact>0</collide_without_contact>
              <collide_without_contact_bitmask>1</collide_without_contact_bitmask>
              <collide_bitmask>1</collide_bitmask>
              <ode>
                <soft_cfm>0</soft_cfm>
                <soft_erp>0.2</soft_erp>
                <kp>1e+13</kp>
                <kd>1</kd>
                <max_vel>0.01</max_vel>
                <min_depth>0</min_depth>
              </ode>
              <bullet>
                <split_impulse>1</split_impulse>
                <split_impulse_penetration_threshold>-0.01</split_impulse_penetration_threshold>
                <soft_cfm>0</soft_cfm>
                <soft_erp>0.2</soft_erp>
                <kp>1e+13</kp>
                <kd>1</kd>
              </bullet>
            </contact>
          </surface>
        </collision>
      </link>
      <static>0</static>
      <allow_auto_disable>1</allow_auto_disable>
      <pose>-8 6.2 0.19837 4e-06 4e-06 -0</pose>
    </model>
    <model name='2outroBigCilindro'>
      <link name='link'>
        <inertial>
          <mass>1</mass>
          <inertia>
            <ixx>0.145833</ixx>
            <ixy>0</ixy>
            <ixz>0</ixz>
            <iyy>0.145833</iyy>
            <iyz>0</iyz>
            <izz>0.125</izz>
          </inertia>
          <pose>0 0 0 0 -0 0</pose>
        </inertial>
        <self_collide>0</self_collide>
        <enable_wind>0</enable_wind>
        <kinematic>0</kinematic>
        <pose>0 0 0 0 -0 0</pose>
        <gravity>1</gravity>
        <visual name='visual'>
          <geometry>
            <cylinder>
              <radius>1.04919</radius>
              <length>0.0737919</length>
            </cylinder>
          </geometry>
          <material>
            <script>
              <name>Gazebo/Grey</name>
              <uri>file://media/materials/scripts/gazebo.material</uri>
            </script>
            <shader type='pixel'>
              <normal_map>__default__</normal_map>
            </shader>
            <ambient>0.2 0.1 0.1 1</ambient>
            <diffuse>0.2 0.1 0.1 1</diffuse>
            <specular>0.2 0.11 0.11 1</specular>
            <emissive>0.2 0.1 0.1 1</emissive>
          </material>
          <pose>0 0 0 0 -0 0</pose>
          <transparency>0</transparency>
          <cast_shadows>1</cast_shadows>
        </visual>
        <collision name='collision'>
          <laser_retro>0</laser_retro>
          <max_contacts>10</max_contacts>
          <pose>0 0 0 0 -0 0</pose>
          <geometry>
            <cylinder>
              <radius>1.04919</radius>
              <length>0.073792</length>
            </cylinder>
          </geometry>
          <surface>
            <friction>
              <ode>
                <mu>1</mu>
                <mu2>1</mu2>
                <fdir1>0 0 0</fdir1>
                <slip1>0</slip1>
                <slip2>0</slip2>
              </ode>
              <torsional>
                <coefficient>1</coefficient>
                <patch_radius>0</patch_radius>
                <surface_radius>0</surface_radius>
                <use_patch_radius>1</use_patch_radius>
                <ode>
                  <slip>0</slip>
                </ode>
              </torsional>
            </friction>
            <bounce>
              <restitution_coefficient>0</restitution_coefficient>
              <threshold>1e+06</threshold>
            </bounce>
            <contact>
              <collide_without_contact>0</collide_without_contact>
              <collide_without_contact_bitmask>1</collide_without_contact_bitmask>
              <collide_bitmask>1</collide_bitmask>
              <ode>
                <soft_cfm>0</soft_cfm>
                <soft_erp>0.2</soft_erp>
                <kp>1e+13</kp>
                <kd>1</kd>
                <max_vel>0.01</max_vel>
                <min_depth>0</min_depth>
              </ode>
              <bullet>
                <split_impulse>1</split_impulse>
                <split_impulse_penetration_threshold>-0.01</split_impulse_penetration_threshold>
                <soft_cfm>0</soft_cfm>
                <soft_erp>0.2</soft_erp>
                <kp>1e+13</kp>
                <kd>1</kd>
              </bullet>
            </contact>
          </surface>
        </collision>
      </link>
      <static>0</static>
      <allow_auto_disable>1</allow_auto_disable>
      <pose>-7.36421 -6.43363 0.19837 4e-06 4e-06 -0</pose>
    </model>
    <light name='sun_clone' type='directional'>
      <pose>13.3913 1.36485 5 0 -0 0</pose>
      <diffuse>0.8 0.8 0.8 1</diffuse>
      <specular>0.2 0.2 0.2 1</specular>
      <direction>-0.483368 0.096674 -0.870063</direction>
      <attenuation>
        <range>1000</range>
        <constant>0.9</constant>
        <linear>0.01</linear>
        <quadratic>0.001</quadratic>
      </attenuation>
      <cast_shadows>1</cast_shadows>
      <spot>
        <inner_angle>0</inner_angle>
        <outer_angle>0</outer_angle>
        <falloff>0</falloff>
      </spot>
    </light>
    <model name='robot1'>
      <pose>-8.06514 3.24018 0.100758 9e-06 -0 0.039965</pose>
      <link name='base_link'>
        <pose>-0.075714 -0 0.0875 0 -0 0</pose>
        <inertial>
          <mass>1.14395</mass>
          <inertia>
            <ixx>0.126164</ixx>
            <ixy>0</ixy>
            <ixz>0</ixz>
            <iyy>0.416519</iyy>
            <iyz>0</iyz>
            <izz>0.481014</izz>
          </inertia>
          <pose>0 0 0 0 -0 0</pose>
        </inertial>
        <visual name='visual'>
          <geometry>
            <box>
              <size>1.00571 0.5 0.284363</size>
            </box>
          </geometry>
          <material>
            <ambient>1 0.6 0.4 1</ambient>
            <diffuse>1 0.6 0.4 1</diffuse>
            <specular>1 0.8 0.6 1</specular>
          </material>
        </visual>
        <collision name='collision'>
          <geometry>
            <box>
              <size>1.00571 0.5 0.284363</size>
            </box>
          </geometry>
          <max_contacts>10</max_contacts>
          <surface>
            <contact>
              <ode/>
            </contact>
            <bounce/>
            <friction>
              <torsional>
                <ode/>
              </torsional>
              <ode/>
            </friction>
          </surface>
        </collision>
        <self_collide>0</self_collide>
        <enable_wind>0</enable_wind>
        <kinematic>0</kinematic>
      </link>
      <link name='left_wheel'>
        <pose>0.277142 0.312515 -0.0125 -1.5707 0 0</pose>
        <inertial>
          <mass>2</mass>
          <inertia>
            <ixx>0.145833</ixx>
            <ixy>0</ixy>
            <ixz>0</ixz>
            <iyy>0.145833</iyy>
            <iyz>0</iyz>
            <izz>0.125</izz>
          </inertia>
          <pose>0 0 0 0 -0 0</pose>
        </inertial>
        <visual name='visual'>
          <geometry>
            <sphere>
              <radius>0.15</radius>
            </sphere>
          </geometry>
          <material>
            <ambient>0.1 0.1 0.1 1</ambient>
            <diffuse>0.2 0.2 0.2 1</diffuse>
            <specular>0.3 0.3 0.3 1</specular>
          </material>
        </visual>
        <collision name='collision'>
          <geometry>
            <sphere>
              <radius>0.15</radius>
            </sphere>
          </geometry>
          <surface>
            <friction>
              <ode>
                <mu>1</mu>
                <mu2>1</mu2>
                <slip1>0</slip1>
                <slip2>0</slip2>
              </ode>
              <torsional>
                <ode/>
              </torsional>
            </friction>
            <contact>
              <ode>
                <soft_cfm>0</soft_cfm>
                <soft_erp>0.2</soft_erp>
                <kp>1e+13</kp>
                <kd>1</kd>
                <max_vel>0.01</max_vel>
                <min_depth>0.01</min_depth>
              </ode>
            </contact>
            <bounce/>
          </surface>
          <max_contacts>10</max_contacts>
        </collision>
        <self_collide>0</self_collide>
        <enable_wind>0</enable_wind>
        <kinematic>0</kinematic>
      </link>
      <link name='right_wheel'>
        <pose>0.277141 -0.312515 -0.0125 -1.5707 0 0</pose>
        <inertial>
          <mass>2</mass>
          <inertia>
            <ixx>0.145833</ixx>
            <ixy>0</ixy>
            <ixz>0</ixz>
            <iyy>0.145833</iyy>
            <iyz>0</iyz>
            <izz>0.125</izz>
          </inertia>
          <pose>0 0 0 0 -0 0</pose>
        </inertial>
        <visual name='visual'>
          <geometry>
            <sphere>
              <radius>0.15</radius>
            </sphere>
          </geometry>
          <material>
            <ambient>0.1 0.1 0.1 1</ambient>
            <diffuse>0.2 0.2 0.2 1</diffuse>
            <specular>0.3 0.3 0.3 1</specular>
          </material>
        </visual>
        <collision name='collision'>
          <geometry>
            <sphere>
              <radius>0.15</radius>
            </sphere>
          </geometry>
          <surface>
            <friction>
              <ode>
                <mu>1</mu>
                <mu2>1</mu2>
                <slip1>0</slip1>
                <slip2>0</slip2>
              </ode>
              <torsional>
                <ode/>
              </torsional>
            </friction>
            <contact>
              <ode>
                <soft_cfm>0</soft_cfm>
                <soft_erp>0.2</soft_erp>
                <kp>1e+13</kp>
                <kd>1</kd>
                <max_vel>0.01</max_vel>
                <min_depth>0.01</min_depth>
              </ode>
            </contact>
            <bounce/>
          </surface>
          <max_contacts>10</max_contacts>
        </collision>
        <self_collide>0</self_collide>
        <enable_wind>0</enable_wind>
        <kinematic>0</kinematic>
      </link>
      <link name='caster'>
        <pose>-0.478569 -0 -0.0625 0 -0 0</pose>
        <inertial>
          <mass>1</mass>
          <inertia>
            <ixx>0.1</ixx>
            <ixy>0</ixy>
            <ixz>0</ixz>
            <iyy>0.1</iyy>
            <iyz>0</iyz>
            <izz>0.1</izz>
          </inertia>
          <pose>0 0 0 0 -0 0</pose>
        </inertial>
        <visual name='visual'>
          <geometry>
            <sphere>
              <radius>0.1</radius>
            </sphere>
          </geometry>
          <material>
            <ambient>0.1 0.1 0.1 1</ambient>
            <diffuse>0.2 0.2 0.2 1</diffuse>
            <specular>0.3 0.3 0.3 1</specular>
          </material>
        </visual>
        <collision name='collision'>
          <geometry>
            <sphere>
              <radius>0.1</radius>
            </sphere>
          </geometry>
          <max_contacts>10</max_contacts>
          <surface>
            <contact>
              <ode/>
            </contact>
            <bounce/>
            <friction>
              <torsional>
                <ode/>
              </torsional>
              <ode/>
            </friction>
          </surface>
        </collision>
        <self_collide>0</self_collide>
        <enable_wind>0</enable_wind>
        <kinematic>0</kinematic>
      </link>
      <joint name='left_wheel_joint' type='revolute'>
        <parent>base_link</parent>
        <child>left_wheel</child>
        <axis>
          <xyz>0 0 1</xyz>
          <limit>
            <lower>-1.79769e+308</lower>
            <upper>1.79769e+308</upper>
          </limit>
          <dynamics>
            <spring_reference>0</spring_reference>
            <spring_stiffness>0</spring_stiffness>
          </dynamics>
        </axis>
      </joint>
      <joint name='right_wheel_joint' type='revolute'>
        <parent>base_link</parent>
        <child>right_wheel</child>
        <axis>
          <xyz>0 0 1</xyz>
          <limit>
            <lower>-1.79769e+308</lower>
            <upper>1.79769e+308</upper>
          </limit>
          <dynamics>
            <spring_reference>0</spring_reference>
            <spring_stiffness>0</spring_stiffness>
          </dynamics>
        </axis>
      </joint>
      <joint name='caster_wheel' type='ball'>
        <parent>base_link</parent>
        <child>caster</child>
      </joint>
      <plugin name='gazebo_ros_diff_drive' filename='libgazebo_ros_diff_drive.so'>
        <ros>
          <namespace>/robot1</namespace>
          <remapping>odom:=odom</remapping>
        </ros>
        <publishOdomTf>1</publishOdomTf>
        <commandTopic>cmd_vel</commandTopic>
        <odometryTopic>odom</odometryTopic>
        <odometrySource>WORLD</odometrySource>
        <publish_odom>1</publish_odom>
        <robotBaseFrame>base_link</robotBaseFrame>
        <left_joint>left_wheel_joint</left_joint>
        <right_joint>right_wheel_joint</right_joint>
      </plugin>
    </model>
    <model name='robot2'>
      <pose>-8.20819 1.06742 0.100758 9e-06 0 0.012346</pose>
      <link name='base_link'>
        <pose>-0.075714 -0 0.0875 0 -0 0</pose>
        <inertial>
          <mass>1.14395</mass>
          <inertia>
            <ixx>0.126164</ixx>
            <ixy>0</ixy>
            <ixz>0</ixz>
            <iyy>0.416519</iyy>
            <iyz>0</iyz>
            <izz>0.481014</izz>
          </inertia>
          <pose>0 0 0 0 -0 0</pose>
        </inertial>
        <visual name='visual'>
          <geometry>
            <box>
              <size>1.00571 0.5 0.284363</size>
            </box>
          </geometry>
          <material>
            <ambient>1 0.75 0.8 1</ambient>
            <diffuse>1 0.75 0.8 1</diffuse>
            <specular>1 0.8 0.8 1</specular>
          </material>
        </visual>
        <collision name='collision'>
          <geometry>
            <box>
              <size>1.00571 0.5 0.284363</size>
            </box>
          </geometry>
          <max_contacts>10</max_contacts>
          <surface>
            <contact>
              <ode/>
            </contact>
            <bounce/>
            <friction>
              <torsional>
                <ode/>
              </torsional>
              <ode/>
            </friction>
          </surface>
        </collision>
        <self_collide>0</self_collide>
        <enable_wind>0</enable_wind>
        <kinematic>0</kinematic>
      </link>
      <link name='left_wheel'>
        <pose>0.277142 0.312515 -0.0125 -1.5707 0 0</pose>
        <inertial>
          <mass>2</mass>
          <inertia>
            <ixx>0.145833</ixx>
            <ixy>0</ixy>
            <ixz>0</ixz>
            <iyy>0.145833</iyy>
            <iyz>0</iyz>
            <izz>0.125</izz>
          </inertia>
          <pose>0 0 0 0 -0 0</pose>
        </inertial>
        <visual name='visual'>
          <geometry>
            <sphere>
              <radius>0.15</radius>
            </sphere>
          </geometry>
          <material>
            <ambient>0.1 0.1 0.1 1</ambient>
            <diffuse>0.2 0.2 0.2 1</diffuse>
            <specular>0.3 0.3 0.3 1</specular>
          </material>
        </visual>
        <collision name='collision'>
          <geometry>
            <sphere>
              <radius>0.15</radius>
            </sphere>
          </geometry>
          <surface>
            <friction>
              <ode>
                <mu>1</mu>
                <mu2>1</mu2>
                <slip1>0</slip1>
                <slip2>0</slip2>
              </ode>
              <torsional>
                <ode/>
              </torsional>
            </friction>
            <contact>
              <ode>
                <soft_cfm>0</soft_cfm>
                <soft_erp>0.2</soft_erp>
                <kp>1e+13</kp>
                <kd>1</kd>
                <max_vel>0.01</max_vel>
                <min_depth>0.01</min_depth>
              </ode>
            </contact>
            <bounce/>
          </surface>
          <max_contacts>10</max_contacts>
        </collision>
        <self_collide>0</self_collide>
        <enable_wind>0</enable_wind>
        <kinematic>0</kinematic>
      </link>
      <link name='right_wheel'>
        <pose>0.277141 -0.312515 -0.0125 -1.5707 0 0</pose>
        <inertial>
          <mass>2</mass>
          <inertia>
            <ixx>0.145833</ixx>
            <ixy>0</ixy>
            <ixz>0</ixz>
            <iyy>0.145833</iyy>
            <iyz>0</iyz>
            <izz>0.125</izz>
          </inertia>
          <pose>0 0 0 0 -0 0</pose>
        </inertial>
        <visual name='visual'>
          <geometry>
            <sphere>
              <radius>0.15</radius>
            </sphere>
          </geometry>
          <material>
            <ambient>0.1 0.1 0.1 1</ambient>
            <diffuse>0.2 0.2 0.2 1</diffuse>
            <specular>0.3 0.3 0.3 1</specular>
          </material>
        </visual>
        <collision name='collision'>
          <geometry>
            <sphere>
              <radius>0.15</radius>
            </sphere>
          </geometry>
          <surface>
            <friction>
              <ode>
                <mu>1</mu>
                <mu2>1</mu2>
                <slip1>0</slip1>
                <slip2>0</slip2>
              </ode>
              <torsional>
                <ode/>
              </torsional>
            </friction>
            <contact>
              <ode>
                <soft_cfm>0</soft_cfm>
                <soft_erp>0.2</soft_erp>
                <kp>1e+13</kp>
                <kd>1</kd>
                <max_vel>0.01</max_vel>
                <min_depth>0.01</min_depth>
              </ode>
            </contact>
            <bounce/>
          </surface>
          <max_contacts>10</max_contacts>
        </collision>
        <self_collide>0</self_collide>
        <enable_wind>0</enable_wind>
        <kinematic>0</kinematic>
      </link>
      <link name='caster'>
        <pose>-0.478569 -0 -0.0625 0 -0 0</pose>
        <inertial>
          <mass>1</mass>
          <inertia>
            <ixx>0.1</ixx>
            <ixy>0</ixy>
            <ixz>0</ixz>
            <iyy>0.1</iyy>
            <iyz>0</iyz>
            <izz>0.1</izz>
          </inertia>
          <pose>0 0 0 0 -0 0</pose>
        </inertial>
        <visual name='visual'>
          <geometry>
            <sphere>
              <radius>0.1</radius>
            </sphere>
          </geometry>
          <material>
            <ambient>0.1 0.1 0.1 1</ambient>
            <diffuse>0.2 0.2 0.2 1</diffuse>
            <specular>0.3 0.3 0.3 1</specular>
          </material>
        </visual>
        <collision name='collision'>
          <geometry>
            <sphere>
              <radius>0.1</radius>
            </sphere>
          </geometry>
          <max_contacts>10</max_contacts>
          <surface>
            <contact>
              <ode/>
            </contact>
            <bounce/>
            <friction>
              <torsional>
                <ode/>
              </torsional>
              <ode/>
            </friction>
          </surface>
        </collision>
        <self_collide>0</self_collide>
        <enable_wind>0</enable_wind>
        <kinematic>0</kinematic>
      </link>
      <joint name='left_wheel_joint' type='revolute'>
        <parent>base_link</parent>
        <child>left_wheel</child>
        <axis>
          <xyz>0 0 1</xyz>
          <limit>
            <lower>-1.79769e+308</lower>
            <upper>1.79769e+308</upper>
          </limit>
          <dynamics>
            <spring_reference>0</spring_reference>
            <spring_stiffness>0</spring_stiffness>
          </dynamics>
        </axis>
      </joint>
      <joint name='right_wheel_joint' type='revolute'>
        <parent>base_link</parent>
        <child>right_wheel</child>
        <axis>
          <xyz>0 0 1</xyz>
          <limit>
            <lower>-1.79769e+308</lower>
            <upper>1.79769e+308</upper>
          </limit>
          <dynamics>
            <spring_reference>0</spring_reference>
            <spring_stiffness>0</spring_stiffness>
          </dynamics>
        </axis>
      </joint>
      <joint name='caster_wheel' type='ball'>
        <parent>base_link</parent>
        <child>caster</child>
      </joint>
      <plugin name='gazebo_ros_diff_drive' filename='libgazebo_ros_diff_drive.so'>
        <ros>
          <namespace>/robot2</namespace>
          <remapping>odom:=odom</remapping>
        </ros>
        <publishOdomTf>1</publishOdomTf>
        <commandTopic>cmd_vel</commandTopic>
        <odometryTopic>odom</odometryTopic>
        <odometrySource>WORLD</odometrySource>
        <publish_odom>1</publish_odom>
        <robotBaseFrame>base_link</robotBaseFrame>
        <left_joint>left_wheel_joint</left_joint>
        <right_joint>right_wheel_joint</right_joint>
      </plugin>
    </model>
    <model name='robot3'>
      <pose>-8.23759 -1.21494 0.201518 0 -0 0.021201</pose>
      <link name='base_link'>
        <pose>-0.075714 -0 0.0875 0 -0 0</pose>
        <inertial>
          <mass>0.5</mass>
          <inertia>
            <ixx>0.01577</ixx>
            <ixy>0</ixy>
            <ixz>0</ixz>
            <iyy>0.20826</iyy>
            <iyz>0</iyz>
            <izz>0.24051</izz>
          </inertia>
          <pose>0 0 0 0 -0 0</pose>
        </inertial>
        <visual name='visual'>
          <geometry>
            <box>
              <size>1.00571 0.5 0.284363</size>
            </box>
          </geometry>
          <material>
            <ambient>0.54 0.81 0.94 1</ambient>
            <diffuse>0.54 0.81 0.94 1</diffuse>
            <specular>0.6 0.9 1 1</specular>
          </material>
        </visual>
        <collision name='collision'>
          <geometry>
            <box>
              <size>1.00571 0.5 0.284363</size>
            </box>
          </geometry>
          <max_contacts>10</max_contacts>
          <surface>
            <contact>
              <ode/>
            </contact>
            <bounce/>
            <friction>
              <torsional>
                <ode/>
              </torsional>
              <ode/>
            </friction>
          </surface>
        </collision>
        <self_collide>0</self_collide>
        <enable_wind>0</enable_wind>
        <kinematic>0</kinematic>
      </link>
      <link name='left_wheel'>
        <pose>0.277142 0.312514 -0.0125 -1.5707 0 0</pose>
        <inertial>
          <mass>1</mass>
          <inertia>
            <ixx>0.0729165</ixx>
            <ixy>0</ixy>
            <ixz>0</ixz>
            <iyy>0.0729165</iyy>
            <iyz>0</iyz>
            <izz>0.0625</izz>
          </inertia>
          <pose>0 0 0 0 -0 0</pose>
        </inertial>
        <visual name='visual'>
          <geometry>
            <sphere>
              <radius>0.15</radius>
            </sphere>
          </geometry>
          <material>
            <ambient>0.1 0.1 0.1 1</ambient>
            <diffuse>0.2 0.2 0.2 1</diffuse>
            <specular>0.3 0.3 0.3 1</specular>
          </material>
        </visual>
        <collision name='collision'>
          <geometry>
            <sphere>
              <radius>0.15</radius>
            </sphere>
          </geometry>
          <surface>
            <friction>
              <ode>
                <mu>1</mu>
                <mu2>1</mu2>
                <slip1>0</slip1>
                <slip2>0</slip2>
              </ode>
              <torsional>
                <ode/>
              </torsional>
            </friction>
            <contact>
              <ode>
                <soft_cfm>0</soft_cfm>
                <soft_erp>0.2</soft_erp>
                <kp>1e+13</kp>
                <kd>1</kd>
                <max_vel>0.01</max_vel>
                <min_depth>0.01</min_depth>
              </ode>
            </contact>
            <bounce/>
          </surface>
          <max_contacts>10</max_contacts>
        </collision>
        <self_collide>0</self_collide>
        <enable_wind>0</enable_wind>
        <kinematic>0</kinematic>
      </link>
      <link name='right_wheel'>
        <pose>0.277141 -0.312514 -0.0125 -1.5707 0 0</pose>
        <inertial>
          <mass>1</mass>
          <inertia>
            <ixx>0.0729165</ixx>
            <ixy>0</ixy>
            <ixz>0</ixz>
            <iyy>0.0729165</iyy>
            <iyz>0</iyz>
            <izz>0.0625</izz>
          </inertia>
          <pose>0 0 0 0 -0 0</pose>
        </inertial>
        <visual name='visual'>
          <geometry>
            <sphere>
              <radius>0.15</radius>
            </sphere>
          </geometry>
          <material>
            <ambient>0.1 0.1 0.1 1</ambient>
            <diffuse>0.2 0.2 0.2 1</diffuse>
            <specular>0.3 0.3 0.3 1</specular>
          </material>
        </visual>
        <collision name='collision'>
          <geometry>
            <sphere>
              <radius>0.15</radius>
            </sphere>
          </geometry>
          <surface>
            <friction>
              <ode>
                <mu>1</mu>
                <mu2>1</mu2>
                <slip1>0</slip1>
                <slip2>0</slip2>
              </ode>
              <torsional>
                <ode/>
              </torsional>
            </friction>
            <contact>
              <ode>
                <soft_cfm>0</soft_cfm>
                <soft_erp>0.2</soft_erp>
                <kp>1e+13</kp>
                <kd>1</kd>
                <max_vel>0.01</max_vel>
                <min_depth>0.01</min_depth>
              </ode>
            </contact>
            <bounce/>
          </surface>
          <max_contacts>10</max_contacts>
        </collision>
        <self_collide>0</self_collide>
        <enable_wind>0</enable_wind>
        <kinematic>0</kinematic>
      </link>
      <link name='caster'>
        <pose>-0.478569 -0 -0.0625 0 -0 0</pose>
        <inertial>
          <mass>0.5</mass>
          <inertia>
            <ixx>0.025</ixx>
            <ixy>0</ixy>
            <ixz>0</ixz>
            <iyy>0.025</iyy>
            <iyz>0</iyz>
            <izz>0.025</izz>
          </inertia>
          <pose>0 0 0 0 -0 0</pose>
        </inertial>
        <visual name='visual'>
          <geometry>
            <sphere>
              <radius>0.1</radius>
            </sphere>
          </geometry>
          <material>
            <ambient>0.1 0.1 0.1 1</ambient>
            <diffuse>0.2 0.2 0.2 1</diffuse>
            <specular>0.3 0.3 0.3 1</specular>
          </material>
        </visual>
        <collision name='collision'>
          <geometry>
            <sphere>
              <radius>0.1</radius>
            </sphere>
          </geometry>
          <max_contacts>10</max_contacts>
          <surface>
            <contact>
              <ode/>
            </contact>
            <bounce/>
            <friction>
              <torsional>
                <ode/>
              </torsional>
              <ode/>
            </friction>
          </surface>
        </collision>
        <self_collide>0</self_collide>
        <enable_wind>0</enable_wind>
        <kinematic>0</kinematic>
      </link>
      <joint name='left_wheel_joint' type='revolute'>
        <parent>base_link</parent>
        <child>left_wheel</child>
        <axis>
          <xyz>0 0 1</xyz>
          <limit>
            <lower>-1.79769e+308</lower>
            <upper>1.79769e+308</upper>
          </limit>
          <dynamics>
            <spring_reference>0</spring_reference>
            <spring_stiffness>0</spring_stiffness>
          </dynamics>
        </axis>
      </joint>
      <joint name='right_wheel_joint' type='revolute'>
        <parent>base_link</parent>
        <child>right_wheel</child>
        <axis>
          <xyz>0 0 1</xyz>
          <limit>
            <lower>-1.79769e+308</lower>
            <upper>1.79769e+308</upper>
          </limit>
          <dynamics>
            <spring_reference>0</spring_reference>
            <spring_stiffness>0</spring_stiffness>
          </dynamics>
        </axis>
      </joint>
      <joint name='caster_wheel' type='ball'>
        <parent>base_link</parent>
        <child>caster</child>
      </joint>
      <plugin name='gazebo_ros_diff_drive' filename='libgazebo_ros_diff_drive.so'>
        <ros>
          <namespace>/robot3</namespace>
          <remapping>odom:=odom</remapping>
        </ros>
        <publishOdomTf>1</publishOdomTf>
        <commandTopic>cmd_vel</commandTopic>
        <odometryTopic>odom</odometryTopic>
        <odometrySource>WORLD</odometrySource>
        <publish_odom>1</publish_odom>
        <robotBaseFrame>base_link</robotBaseFrame>
        <left_joint>left_wheel_joint</left_joint>
        <right_joint>right_wheel_joint</right_joint>
      </plugin>
    </model>
    <model name='robot4'>
      <pose>-8.21581 -2.81322 0.201518 0 0 -0.000819</pose>
      <link name='base_link'>
        <pose>-0.151427 -0 0.175 0 -0 0</pose>
        <inertial>
          <mass>0.571975</mass>
          <inertia>
            <ixx>0.015791</ixx>
            <ixy>0</ixy>
            <ixz>0</ixz>
            <iyy>0.20826</iyy>
            <iyz>0</iyz>
            <izz>0.240507</izz>
          </inertia>
          <pose>0 0 0 0 -0 0</pose>
        </inertial>
        <visual name='visual'>
          <geometry>
            <box>
              <size>1.00571 0.5 0.284363</size>
            </box>
          </geometry>
          <material>
            <ambient>0.6 1 0.6 1</ambient>
            <diffuse>0.6 1 0.6 1</diffuse>
            <specular>0.8 1 0.8 1</specular>
          </material>
        </visual>
        <collision name='collision'>
          <geometry>
            <box>
              <size>1.00571 0.5 0.284363</size>
            </box>
          </geometry>
          <max_contacts>10</max_contacts>
          <surface>
            <contact>
              <ode/>
            </contact>
            <bounce/>
            <friction>
              <torsional>
                <ode/>
              </torsional>
              <ode/>
            </friction>
          </surface>
        </collision>
        <self_collide>0</self_collide>
        <enable_wind>0</enable_wind>
        <kinematic>0</kinematic>
      </link>
      <link name='left_wheel'>
        <pose>0.277141 0.312515 -0.0125 -1.5707 0 0</pose>
        <inertial>
          <mass>0.5</mass>
          <inertia>
            <ixx>0.0364583</ixx>
            <ixy>0</ixy>
            <ixz>0</ixz>
            <iyy>0.0364583</iyy>
            <iyz>0</iyz>
            <izz>0.03125</izz>
          </inertia>
          <pose>0 0 0 0 -0 0</pose>
        </inertial>
        <visual name='visual'>
          <geometry>
            <sphere>
              <radius>0.15</radius>
            </sphere>
          </geometry>
          <material>
            <ambient>0.1 0.1 0.1 1</ambient>
            <diffuse>0.2 0.2 0.2 1</diffuse>
            <specular>0.3 0.3 0.3 1</specular>
          </material>
        </visual>
        <collision name='collision'>
          <geometry>
            <sphere>
              <radius>0.15</radius>
            </sphere>
          </geometry>
          <surface>
            <friction>
              <ode>
                <mu>1</mu>
                <mu2>1</mu2>
                <slip1>0</slip1>
                <slip2>0</slip2>
              </ode>
              <torsional>
                <ode/>
              </torsional>
            </friction>
            <contact>
              <ode>
                <soft_cfm>0</soft_cfm>
                <soft_erp>0.2</soft_erp>
                <kp>1e+13</kp>
                <kd>1</kd>
                <max_vel>0.01</max_vel>
                <min_depth>0.01</min_depth>
              </ode>
            </contact>
            <bounce/>
          </surface>
          <max_contacts>10</max_contacts>
        </collision>
        <self_collide>0</self_collide>
        <enable_wind>0</enable_wind>
        <kinematic>0</kinematic>
      </link>
      <link name='right_wheel'>
        <pose>0.277141 -0.312515 -0.0125 -1.5707 0 0</pose>
        <inertial>
          <mass>0.5</mass>
          <inertia>
            <ixx>0.0364583</ixx>
            <ixy>0</ixy>
            <ixz>0</ixz>
            <iyy>0.0364583</iyy>
            <iyz>0</iyz>
            <izz>0.03125</izz>
          </inertia>
          <pose>0 0 0 0 -0 0</pose>
        </inertial>
        <visual name='visual'>
          <geometry>
            <sphere>
              <radius>0.15</radius>
            </sphere>
          </geometry>
          <material>
            <ambient>0.1 0.1 0.1 1</ambient>
            <diffuse>0.2 0.2 0.2 1</diffuse>
            <specular>0.3 0.3 0.3 1</specular>
          </material>
        </visual>
        <collision name='collision'>
          <geometry>
            <sphere>
              <radius>0.15</radius>
            </sphere>
          </geometry>
          <surface>
            <friction>
              <ode>
                <mu>1</mu>
                <mu2>1</mu2>
                <slip1>0</slip1>
                <slip2>0</slip2>
              </ode>
              <torsional>
                <ode/>
              </torsional>
            </friction>
            <contact>
              <ode>
                <soft_cfm>0</soft_cfm>
                <soft_erp>0.2</soft_erp>
                <kp>1e+13</kp>
                <kd>1</kd>
                <max_vel>0.01</max_vel>
                <min_depth>0.01</min_depth>
              </ode>
            </contact>
            <bounce/>
          </surface>
          <max_contacts>10</max_contacts>
        </collision>
        <self_collide>0</self_collide>
        <enable_wind>0</enable_wind>
        <kinematic>0</kinematic>
      </link>
      <link name='caster'>
        <pose>-0.478569 -0 -0.0625 0 -0 0</pose>
        <inertial>
          <mass>0.5</mass>
          <inertia>
            <ixx>0.025</ixx>
            <ixy>0</ixy>
            <ixz>0</ixz>
            <iyy>0.025</iyy>
            <iyz>0</iyz>
            <izz>0.025</izz>
          </inertia>
          <pose>0 0 0 0 -0 0</pose>
        </inertial>
        <visual name='visual'>
          <geometry>
            <sphere>
              <radius>0.1</radius>
            </sphere>
          </geometry>
          <material>
            <ambient>0.1 0.1 0.1 1</ambient>
            <diffuse>0.2 0.2 0.2 1</diffuse>
            <specular>0.3 0.3 0.3 1</specular>
          </material>
        </visual>
        <collision name='collision'>
          <geometry>
            <sphere>
              <radius>0.1</radius>
            </sphere>
          </geometry>
          <max_contacts>10</max_contacts>
          <surface>
            <contact>
              <ode/>
            </contact>
            <bounce/>
            <friction>
              <torsional>
                <ode/>
              </torsional>
              <ode/>
            </friction>
          </surface>
        </collision>
        <self_collide>0</self_collide>
        <enable_wind>0</enable_wind>
        <kinematic>0</kinematic>
      </link>
      <joint name='left_wheel_joint' type='revolute'>
        <parent>base_link</parent>
        <child>left_wheel</child>
        <axis>
          <xyz>0 0 1</xyz>
          <limit>
            <lower>-1.79769e+308</lower>
            <upper>1.79769e+308</upper>
          </limit>
          <dynamics>
            <spring_reference>0</spring_reference>
            <spring_stiffness>0</spring_stiffness>
          </dynamics>
        </axis>
      </joint>
      <joint name='right_wheel_joint' type='revolute'>
        <parent>base_link</parent>
        <child>right_wheel</child>
        <axis>
          <xyz>0 0 1</xyz>
          <limit>
            <lower>-1.79769e+308</lower>
            <upper>1.79769e+308</upper>
          </limit>
          <dynamics>
            <spring_reference>0</spring_reference>
            <spring_stiffness>0</spring_stiffness>
          </dynamics>
        </axis>
      </joint>
      <joint name='caster_wheel' type='ball'>
        <parent>base_link</parent>
        <child>caster</child>
      </joint>
      <plugin name='gazebo_ros_diff_drive' filename='libgazebo_ros_diff_drive.so'>
        <ros>
          <namespace>/robot4</namespace>
          <remapping>odom:=odom</remapping>
        </ros>
        <publishOdomTf>1</publishOdomTf>
        <commandTopic>cmd_vel</commandTopic>
        <odometryTopic>odom</odometryTopic>
        <odometrySource>WORLD</odometrySource>
        <publish_odom>1</publish_odom>
        <robotBaseFrame>base_link</robotBaseFrame>
        <left_joint>left_wheel_joint</left_joint>
        <right_joint>right_wheel_joint</right_joint>
      </plugin>
    </model>
  </world>
</sdf>
