<sdf version='1.7'>
  <world name='default'>
    <model name='ground_plane'>
      <static>1</static>
      <link name='link'>
        <collision name='collision'>
          <geometry>
            <plane>
              <normal>0 0 1</normal>
              <size>100 100</size>
            </plane>
          </geometry>
          <surface>
            <friction>
              <ode>
                <mu>100</mu>
                <mu2>50</mu2>
              </ode>
              <torsional>
                <ode/>
              </torsional>
            </friction>
            <contact>
              <ode/>
            </contact>
            <bounce/>
          </surface>
          <max_contacts>10</max_contacts>
        </collision>
        <visual name='visual'>
          <cast_shadows>0</cast_shadows>
          <geometry>
            <plane>
              <normal>0 0 1</normal>
              <size>100 100</size>
            </plane>
          </geometry>
          <material>
            <script>
              <uri>file://media/materials/scripts/gazebo.material</uri>
              <name>Gazebo/Grey</name>
            </script>
          </material>
        </visual>
        <self_collide>0</self_collide>
        <enable_wind>0</enable_wind>
        <kinematic>0</kinematic>
      </link>
    </model>
    <light name='sun' type='directional'>
      <cast_shadows>1</cast_shadows>
      <pose>0 0 10 0 -0 0</pose>
      <diffuse>0.8 0.8 0.8 1</diffuse>
      <specular>0.2 0.2 0.2 1</specular>
      <attenuation>
        <range>1000</range>
        <constant>0.9</constant>
        <linear>0.01</linear>
        <quadratic>0.001</quadratic>
      </attenuation>
      <direction>-0.5 0.1 -0.9</direction>
      <spot>
        <inner_angle>0</inner_angle>
        <outer_angle>0</outer_angle>
        <falloff>0</falloff>
      </spot>
    </light>
    <gravity>0 0 -9.8</gravity>
    <magnetic_field>6e-06 2.3e-05 -4.2e-05</magnetic_field>
    <atmosphere type='adiabatic'/>
    <physics type='ode'>
      <max_step_size>0.001</max_step_size>
      <real_time_factor>1</real_time_factor>
      <real_time_update_rate>1000</real_time_update_rate>
    </physics>
    <scene>
      <ambient>0.4 0.4 0.4 1</ambient>
      <background>0.7 0.7 0.7 1</background>
      <shadows>1</shadows>
    </scene>
    <audio>
      <device>default</device>
    </audio>
    <wind/>
    <spherical_coordinates>
      <surface_model>EARTH_WGS84</surface_model>
      <latitude_deg>0</latitude_deg>
      <longitude_deg>0</longitude_deg>
      <elevation>0</elevation>
      <heading_deg>0</heading_deg>
    </spherical_coordinates>
    <model name='plant_1A'>
      <static>1</static>
      <link name='link'>
        <visual name='visual'>
          <geometry>
            <mesh>
              <uri>file:///home/violas/ros2_ws/src/plugins/models/plants/PotPlant.dae</uri>
              <scale>0.2 0.2 0.2</scale>
            </mesh>
          </geometry>
        </visual>
        <collision name='collision'>
          <geometry>
            <mesh>
              <uri>file:///home/violas/ros2_ws/src/plugins/models/plants/PotPlant.dae</uri>
              <scale>0.2 0.2 0.2</scale>
            </mesh>
          </geometry>
          <max_contacts>10</max_contacts>
          <surface>
            <contact>
              <ode/>
            </contact>
            <bounce/>
            <friction>
              <torsional>
                <ode/>
              </torsional>
              <ode/>
            </friction>
          </surface>
        </collision>
        <self_collide>0</self_collide>
        <enable_wind>0</enable_wind>
        <kinematic>0</kinematic>
      </link>
    </model>
    <model name='plant_2A'>
      <static>1</static>
      <link name='link'>
        <visual name='visual'>
          <geometry>
            <mesh>
              <uri>file:///home/violas/ros2_ws/src/plugins/models/plants/PotPlant.dae</uri>
              <scale>0.2 0.2 0.2</scale>
            </mesh>
          </geometry>
        </visual>
        <collision name='collision'>
          <geometry>
            <mesh>
              <uri>file:///home/violas/ros2_ws/src/plugins/models/plants/PotPlant.dae</uri>
              <scale>0.2 0.2 0.2</scale>
            </mesh>
          </geometry>
          <max_contacts>10</max_contacts>
          <surface>
            <contact>
              <ode/>
            </contact>
            <bounce/>
            <friction>
              <torsional>
                <ode/>
              </torsional>
              <ode/>
            </friction>
          </surface>
        </collision>
        <self_collide>0</self_collide>
        <enable_wind>0</enable_wind>
        <kinematic>0</kinematic>
      </link>
    </model>
    <model name='plant_3A'>
      <static>1</static>
      <link name='link'>
        <visual name='visual'>
          <geometry>
            <mesh>
              <uri>file:///home/violas/ros2_ws/src/plugins/models/plants/PotPlant.dae</uri>
              <scale>0.2 0.2 0.2</scale>
            </mesh>
          </geometry>
        </visual>
        <collision name='collision'>
          <geometry>
            <mesh>
              <uri>file:///home/violas/ros2_ws/src/plugins/models/plants/PotPlant.dae</uri>
              <scale>0.2 0.2 0.2</scale>
            </mesh>
          </geometry>
          <max_contacts>10</max_contacts>
          <surface>
            <contact>
              <ode/>
            </contact>
            <bounce/>
            <friction>
              <torsional>
                <ode/>
              </torsional>
              <ode/>
            </friction>
          </surface>
        </collision>
        <self_collide>0</self_collide>
        <enable_wind>0</enable_wind>
        <kinematic>0</kinematic>
      </link>
    </model>
    <model name='plant_4A'>
      <static>1</static>
      <link name='link'>
        <visual name='visual'>
          <geometry>
            <mesh>
              <uri>file:///home/violas/ros2_ws/src/plugins/models/plants/PotPlant.dae</uri>
              <scale>0.2 0.2 0.2</scale>
            </mesh>
          </geometry>
        </visual>
        <collision name='collision'>
          <geometry>
            <mesh>
              <uri>file:///home/violas/ros2_ws/src/plugins/models/plants/PotPlant.dae</uri>
              <scale>0.2 0.2 0.2</scale>
            </mesh>
          </geometry>
          <max_contacts>10</max_contacts>
          <surface>
            <contact>
              <ode/>
            </contact>
            <bounce/>
            <friction>
              <torsional>
                <ode/>
              </torsional>
              <ode/>
            </friction>
          </surface>
        </collision>
        <self_collide>0</self_collide>
        <enable_wind>0</enable_wind>
        <kinematic>0</kinematic>
      </link>
    </model>
    <model name='plant_1B'>
      <static>1</static>
      <link name='link'>
        <visual name='visual'>
          <geometry>
            <mesh>
              <uri>file:///home/violas/ros2_ws/src/plugins/models/plants/PotPlant.dae</uri>
              <scale>0.2 0.2 0.2</scale>
            </mesh>
          </geometry>
        </visual>
        <collision name='collision'>
          <geometry>
            <mesh>
              <uri>file:///home/violas/ros2_ws/src/plugins/models/plants/PotPlant.dae</uri>
              <scale>0.2 0.2 0.2</scale>
            </mesh>
          </geometry>
          <max_contacts>10</max_contacts>
          <surface>
            <contact>
              <ode/>
            </contact>
            <bounce/>
            <friction>
              <torsional>
                <ode/>
              </torsional>
              <ode/>
            </friction>
          </surface>
        </collision>
        <self_collide>0</self_collide>
        <enable_wind>0</enable_wind>
        <kinematic>0</kinematic>
      </link>
    </model>
    <model name='plant_2B'>
      <static>1</static>
      <link name='link'>
        <visual name='visual'>
          <geometry>
            <mesh>
              <uri>file:///home/violas/ros2_ws/src/plugins/models/plants/PotPlant.dae</uri>
              <scale>0.2 0.2 0.2</scale>
            </mesh>
          </geometry>
        </visual>
        <collision name='collision'>
          <geometry>
            <mesh>
              <uri>file:///home/violas/ros2_ws/src/plugins/models/plants/PotPlant.dae</uri>
              <scale>0.2 0.2 0.2</scale>
            </mesh>
          </geometry>
          <max_contacts>10</max_contacts>
          <surface>
            <contact>
              <ode/>
            </contact>
            <bounce/>
            <friction>
              <torsional>
                <ode/>
              </torsional>
              <ode/>
            </friction>
          </surface>
        </collision>
        <self_collide>0</self_collide>
        <enable_wind>0</enable_wind>
        <kinematic>0</kinematic>
      </link>
    </model>
    <model name='plant_3B'>
      <static>1</static>
      <link name='link'>
        <visual name='visual'>
          <geometry>
            <mesh>
              <uri>file:///home/violas/ros2_ws/src/plugins/models/plants/PotPlant.dae</uri>
              <scale>0.2 0.2 0.2</scale>
            </mesh>
          </geometry>
        </visual>
        <collision name='collision'>
          <geometry>
            <mesh>
              <uri>file:///home/violas/ros2_ws/src/plugins/models/plants/PotPlant.dae</uri>
              <scale>0.2 0.2 0.2</scale>
            </mesh>
          </geometry>
          <max_contacts>10</max_contacts>
          <surface>
            <contact>
              <ode/>
            </contact>
            <bounce/>
            <friction>
              <torsional>
                <ode/>
              </torsional>
              <ode/>
            </friction>
          </surface>
        </collision>
        <self_collide>0</self_collide>
        <enable_wind>0</enable_wind>
        <kinematic>0</kinematic>
      </link>
    </model>
    <model name='plant_4B'>
      <static>1</static>
      <link name='link'>
        <visual name='visual'>
          <geometry>
            <mesh>
              <uri>file:///home/violas/ros2_ws/src/plugins/models/plants/PotPlant.dae</uri>
              <scale>0.2 0.2 0.2</scale>
            </mesh>
          </geometry>
        </visual>
        <collision name='collision'>
          <geometry>
            <mesh>
              <uri>file:///home/violas/ros2_ws/src/plugins/models/plants/PotPlant.dae</uri>
              <scale>0.2 0.2 0.2</scale>
            </mesh>
          </geometry>
          <max_contacts>10</max_contacts>
          <surface>
            <contact>
              <ode/>
            </contact>
            <bounce/>
            <friction>
              <torsional>
                <ode/>
              </torsional>
              <ode/>
            </friction>
          </surface>
        </collision>
        <self_collide>0</self_collide>
        <enable_wind>0</enable_wind>
        <kinematic>0</kinematic>
      </link>
    </model>
    <model name='plant_1C'>
      <static>1</static>
      <link name='link'>
        <visual name='visual'>
          <geometry>
            <mesh>
              <uri>file:///home/violas/ros2_ws/src/plugins/models/plants/PotPlant.dae</uri>
              <scale>0.2 0.2 0.2</scale>
            </mesh>
          </geometry>
        </visual>
        <collision name='collision'>
          <geometry>
            <mesh>
              <uri>file:///home/violas/ros2_ws/src/plugins/models/plants/PotPlant.dae</uri>
              <scale>0.2 0.2 0.2</scale>
            </mesh>
          </geometry>
          <max_contacts>10</max_contacts>
          <surface>
            <contact>
              <ode/>
            </contact>
            <bounce/>
            <friction>
              <torsional>
                <ode/>
              </torsional>
              <ode/>
            </friction>
          </surface>
        </collision>
        <self_collide>0</self_collide>
        <enable_wind>0</enable_wind>
        <kinematic>0</kinematic>
      </link>
    </model>
    <model name='plant_2C'>
      <static>1</static>
      <link name='link'>
        <visual name='visual'>
          <geometry>
            <mesh>
              <uri>file:///home/violas/ros2_ws/src/plugins/models/plants/PotPlant.dae</uri>
              <scale>0.2 0.2 0.2</scale>
            </mesh>
          </geometry>
        </visual>
        <collision name='collision'>
          <geometry>
            <mesh>
              <uri>file:///home/violas/ros2_ws/src/plugins/models/plants/PotPlant.dae</uri>
              <scale>0.2 0.2 0.2</scale>
            </mesh>
          </geometry>
          <max_contacts>10</max_contacts>
          <surface>
            <contact>
              <ode/>
            </contact>
            <bounce/>
            <friction>
              <torsional>
                <ode/>
              </torsional>
              <ode/>
            </friction>
          </surface>
        </collision>
        <self_collide>0</self_collide>
        <enable_wind>0</enable_wind>
        <kinematic>0</kinematic>
      </link>
    </model>
    <model name='plant_3C'>
      <static>1</static>
      <link name='link'>
        <visual name='visual'>
          <geometry>
            <mesh>
              <uri>file:///home/violas/ros2_ws/src/plugins/models/plants/PotPlant.dae</uri>
              <scale>0.2 0.2 0.2</scale>
            </mesh>
          </geometry>
        </visual>
        <collision name='collision'>
          <geometry>
            <mesh>
              <uri>file:///home/violas/ros2_ws/src/plugins/models/plants/PotPlant.dae</uri>
              <scale>0.2 0.2 0.2</scale>
            </mesh>
          </geometry>
          <max_contacts>10</max_contacts>
          <surface>
            <contact>
              <ode/>
            </contact>
            <bounce/>
            <friction>
              <torsional>
                <ode/>
              </torsional>
              <ode/>
            </friction>
          </surface>
        </collision>
        <self_collide>0</self_collide>
        <enable_wind>0</enable_wind>
        <kinematic>0</kinematic>
      </link>
    </model>
    <model name='plant_4C'>
      <static>1</static>
      <link name='link'>
        <visual name='visual'>
          <geometry>
            <mesh>
              <uri>file:///home/violas/ros2_ws/src/plugins/models/plants/PotPlant.dae</uri>
              <scale>0.2 0.2 0.2</scale>
            </mesh>
          </geometry>
        </visual>
        <collision name='collision'>
          <geometry>
            <mesh>
              <uri>file:///home/violas/ros2_ws/src/plugins/models/plants/PotPlant.dae</uri>
              <scale>0.2 0.2 0.2</scale>
            </mesh>
          </geometry>
          <max_contacts>10</max_contacts>
          <surface>
            <contact>
              <ode/>
            </contact>
            <bounce/>
            <friction>
              <torsional>
                <ode/>
              </torsional>
              <ode/>
            </friction>
          </surface>
        </collision>
        <self_collide>0</self_collide>
        <enable_wind>0</enable_wind>
        <kinematic>0</kinematic>
      </link>
    </model>
    <model name='plant_1D'>
      <static>1</static>
      <link name='link'>
        <visual name='visual'>
          <geometry>
            <mesh>
              <uri>file:///home/violas/ros2_ws/src/plugins/models/plants/PotPlant.dae</uri>
              <scale>0.2 0.2 0.2</scale>
            </mesh>
          </geometry>
        </visual>
        <collision name='collision'>
          <geometry>
            <mesh>
              <uri>file:///home/violas/ros2_ws/src/plugins/models/plants/PotPlant.dae</uri>
              <scale>0.2 0.2 0.2</scale>
            </mesh>
          </geometry>
          <max_contacts>10</max_contacts>
          <surface>
            <contact>
              <ode/>
            </contact>
            <bounce/>
            <friction>
              <torsional>
                <ode/>
              </torsional>
              <ode/>
            </friction>
          </surface>
        </collision>
        <self_collide>0</self_collide>
        <enable_wind>0</enable_wind>
        <kinematic>0</kinematic>
      </link>
    </model>
    <model name='plant_2D'>
      <static>1</static>
      <link name='link'>
        <visual name='visual'>
          <geometry>
            <mesh>
              <uri>file:///home/violas/ros2_ws/src/plugins/models/plants/PotPlant.dae</uri>
              <scale>0.2 0.2 0.2</scale>
            </mesh>
          </geometry>
        </visual>
        <collision name='collision'>
          <geometry>
            <mesh>
              <uri>file:///home/violas/ros2_ws/src/plugins/models/plants/PotPlant.dae</uri>
              <scale>0.2 0.2 0.2</scale>
            </mesh>
          </geometry>
          <max_contacts>10</max_contacts>
          <surface>
            <contact>
              <ode/>
            </contact>
            <bounce/>
            <friction>
              <torsional>
                <ode/>
              </torsional>
              <ode/>
            </friction>
          </surface>
        </collision>
        <self_collide>0</self_collide>
        <enable_wind>0</enable_wind>
        <kinematic>0</kinematic>
      </link>
    </model>
    <model name='plant_3D'>
      <static>1</static>
      <link name='link'>
        <visual name='visual'>
          <geometry>
            <mesh>
              <uri>file:///home/violas/ros2_ws/src/plugins/models/plants/PotPlant.dae</uri>
              <scale>0.2 0.2 0.2</scale>
            </mesh>
          </geometry>
        </visual>
        <collision name='collision'>
          <geometry>
            <mesh>
              <uri>file:///home/violas/ros2_ws/src/plugins/models/plants/PotPlant.dae</uri>
              <scale>0.2 0.2 0.2</scale>
            </mesh>
          </geometry>
          <max_contacts>10</max_contacts>
          <surface>
            <contact>
              <ode/>
            </contact>
            <bounce/>
            <friction>
              <torsional>
                <ode/>
              </torsional>
              <ode/>
            </friction>
          </surface>
        </collision>
        <self_collide>0</self_collide>
        <enable_wind>0</enable_wind>
        <kinematic>0</kinematic>
      </link>
    </model>
    <model name='plant_4D'>
      <static>1</static>
      <link name='link'>
        <visual name='visual'>
          <geometry>
            <mesh>
              <uri>file:///home/violas/ros2_ws/src/plugins/models/plants/PotPlant.dae</uri>
              <scale>0.2 0.2 0.2</scale>
            </mesh>
          </geometry>
        </visual>
        <collision name='collision'>
          <geometry>
            <mesh>
              <uri>file:///home/violas/ros2_ws/src/plugins/models/plants/PotPlant.dae</uri>
              <scale>0.2 0.2 0.2</scale>
            </mesh>
          </geometry>
          <max_contacts>10</max_contacts>
          <surface>
            <contact>
              <ode/>
            </contact>
            <bounce/>
            <friction>
              <torsional>
                <ode/>
              </torsional>
              <ode/>
            </friction>
          </surface>
        </collision>
        <self_collide>0</self_collide>
        <enable_wind>0</enable_wind>
        <kinematic>0</kinematic>
      </link>
    </model>
    <state world_name='default'>
      <sim_time>1507 902000000</sim_time>
      <real_time>214 128488472</real_time>
      <wall_time>1718571571 677959027</wall_time>
      <iterations>213745</iterations>
      <model name='charger'>
        <pose>-8.2 -7 0 0 0 -1.62417</pose>
        <scale>1 1 1</scale>
        <link name='link'>
          <pose>-8.2 -7 0 0 0 -1.62417</pose>
          <velocity>0 0 0 0 -0 0</velocity>
          <acceleration>0 0 0 0 -0 0</acceleration>
          <wrench>0 0 0 0 -0 0</wrench>
        </link>
      </model>
      <model name='ground_plane'>
        <pose>0 0 0 0 -0 0</pose>
        <scale>1 1 1</scale>
        <link name='link'>
          <pose>0 0 0 0 -0 0</pose>
          <velocity>0 0 0 0 -0 0</velocity>
          <acceleration>0 0 0 0 -0 0</acceleration>
          <wrench>0 0 0 0 -0 0</wrench>
        </link>
      </model>
      <model name='mud'>
        <pose>-1 0 0 0 -0 0</pose>
        <scale>1 1 1</scale>
        <link name='link'>
          <pose>-1 0 0 0 -0 0</pose>
          <velocity>0 0 0 0 -0 0</velocity>
          <acceleration>0 0 0 0 -0 0</acceleration>
          <wrench>0 0 0 0 -0 0</wrench>
        </link>
      </model>
      <model name='outroBigCilindro'>
        <pose>-8.51937 3.1811 0.103573 -2e-06 3.4e-05 -0.002829</pose>
        <scale>1 1 0.096562</scale>
        <link name='link'>
          <pose>-8.51937 3.1811 0.103573 -2e-06 3.4e-05 -0.002829</pose>
          <velocity>-0.000664 -0.000111 -0.019903 -0.000975 0.022077 -0.000216</velocity>
          <acceleration>0 0 -9.8 -1e-06 -0 0</acceleration>
          <wrench>0 0 -9.8 0 -0 0</wrench>
        </link>
      </model>
      <model name='outroBigCilindro_clone'>
        <pose>-8.48739 -1.01672 0.103562 -1.2e-05 -5.7e-05 -0.017875</pose>
        <scale>1 1 1</scale>
        <link name='link'>
          <pose>-8.48739 -1.01672 0.103562 -1.2e-05 -5.7e-05 -0.017875</pose>
          <velocity>0.001209 -0.000617 -0.011757 -0.001835 -0.043206 -0.001188</velocity>
          <acceleration>1.23059 0.270867 -21.695 -2.12693 0.68194 -1.40721</acceleration>
          <wrench>1.23059 0.270867 -21.695 0 -0 0</wrench>
        </link>
      </model>
      <model name='outroBigCilindro_clone_0'>
        <pose>-8.46425 -3.11875 0.103582 2.6e-05 -2e-05 0.015704</pose>
        <scale>1 1 1</scale>
        <link name='link'>
          <pose>-8.46425 -3.11875 0.103582 2.6e-05 -2e-05 0.015704</pose>
          <velocity>0 0 0 0 -0 0</velocity>
          <acceleration>0.813399 0.07026 -17.8449 0.594664 -0.17179 -1.67555</acceleration>
          <wrench>0.813399 0.07026 -17.8449 0 -0 0</wrench>
        </link>
      </model>
      <model name='outroBigCilindro_clone_1'>
        <pose>-8.54503 1.08283 0.103584 -1e-05 -1.7e-05 -0.003394</pose>
        <scale>1 1 1</scale>
        <link name='link'>
          <pose>-8.54503 1.08283 0.103584 -1e-05 -1.7e-05 -0.003394</pose>
          <velocity>5.7e-05 0.000535 0.009866 -0.000478 0.000394 0.000124</velocity>
          <acceleration>0.180839 0.466565 52.7875 2.41034 0.196909 -3.01722</acceleration>
          <wrench>0.180839 0.466565 52.7875 0 -0 0</wrench>
        </link>
      </model>
      <model name='plant_1A'>
        <pose>-2 -3 0 0 -0 0</pose>
        <scale>1 1 1</scale>
        <link name='link'>
          <pose>-2 -3 0 0 -0 0</pose>
          <velocity>0 0 0 0 -0 0</velocity>
          <acceleration>0 0 0 0 -0 0</acceleration>
          <wrench>0 0 0 0 -0 0</wrench>
        </link>
      </model>
      <model name='plant_1B'>
        <pose>-1.333 -3 0 0 -0 0</pose>
        <scale>1 1 1</scale>
        <link name='link'>
          <pose>-1.333 -3 0 0 -0 0</pose>
          <velocity>0 0 0 0 -0 0</velocity>
          <acceleration>0 0 0 0 -0 0</acceleration>
          <wrench>0 0 0 0 -0 0</wrench>
        </link>
      </model>
      <model name='plant_1C'>
        <pose>-0.667 -3 0 0 -0 0</pose>
        <scale>1 1 1</scale>
        <link name='link'>
          <pose>-0.667 -3 0 0 -0 0</pose>
          <velocity>0 0 0 0 -0 0</velocity>
          <acceleration>0 0 0 0 -0 0</acceleration>
          <wrench>0 0 0 0 -0 0</wrench>
        </link>
      </model>
      <model name='plant_1D'>
        <pose>0 -3 0 0 -0 0</pose>
        <scale>1 1 1</scale>
        <link name='link'>
          <pose>0 -3 0 0 -0 0</pose>
          <velocity>0 0 0 0 -0 0</velocity>
          <acceleration>0 0 0 0 -0 0</acceleration>
          <wrench>0 0 0 0 -0 0</wrench>
        </link>
      </model>
      <model name='plant_2A'>
        <pose>2 -3 0 0 -0 0</pose>
        <scale>1 1 1</scale>
        <link name='link'>
          <pose>2 -3 0 0 -0 0</pose>
          <velocity>0 0 0 0 -0 0</velocity>
          <acceleration>0 0 0 0 -0 0</acceleration>
          <wrench>0 0 0 0 -0 0</wrench>
        </link>
      </model>
      <model name='plant_2B'>
        <pose>2.667 -3 0 0 -0 0</pose>
        <scale>1 1 1</scale>
        <link name='link'>
          <pose>2.667 -3 0 0 -0 0</pose>
          <velocity>0 0 0 0 -0 0</velocity>
          <acceleration>0 0 0 0 -0 0</acceleration>
          <wrench>0 0 0 0 -0 0</wrench>
        </link>
      </model>
      <model name='plant_2C'>
        <pose>3.333 -3 0 0 -0 0</pose>
        <scale>1 1 1</scale>
        <link name='link'>
          <pose>3.333 -3 0 0 -0 0</pose>
          <velocity>0 0 0 0 -0 0</velocity>
          <acceleration>0 0 0 0 -0 0</acceleration>
          <wrench>0 0 0 0 -0 0</wrench>
        </link>
      </model>
      <model name='plant_2D'>
        <pose>4 -3 0 0 -0 0</pose>
        <scale>1 1 1</scale>
        <link name='link'>
          <pose>4 -3 0 0 -0 0</pose>
          <velocity>0 0 0 0 -0 0</velocity>
          <acceleration>0 0 0 0 -0 0</acceleration>
          <wrench>0 0 0 0 -0 0</wrench>
        </link>
      </model>
      <model name='plant_3A'>
        <pose>-2 3 0 0 -0 0</pose>
        <scale>1 1 1</scale>
        <link name='link'>
          <pose>-2 3 0 0 -0 0</pose>
          <velocity>0 0 0 0 -0 0</velocity>
          <acceleration>0 0 0 0 -0 0</acceleration>
          <wrench>0 0 0 0 -0 0</wrench>
        </link>
      </model>
      <model name='plant_3B'>
        <pose>-1.333 3 0 0 -0 0</pose>
        <scale>1 1 1</scale>
        <link name='link'>
          <pose>-1.333 3 0 0 -0 0</pose>
          <velocity>0 0 0 0 -0 0</velocity>
          <acceleration>0 0 0 0 -0 0</acceleration>
          <wrench>0 0 0 0 -0 0</wrench>
        </link>
      </model>
      <model name='plant_3C'>
        <pose>-0.667 3 0 0 -0 0</pose>
        <scale>1 1 1</scale>
        <link name='link'>
          <pose>-0.667 3 0 0 -0 0</pose>
          <velocity>0 0 0 0 -0 0</velocity>
          <acceleration>0 0 0 0 -0 0</acceleration>
          <wrench>0 0 0 0 -0 0</wrench>
        </link>
      </model>
      <model name='plant_3D'>
        <pose>0 3 0 0 -0 0</pose>
        <scale>1 1 1</scale>
        <link name='link'>
          <pose>0 3 0 0 -0 0</pose>
          <velocity>0 0 0 0 -0 0</velocity>
          <acceleration>0 0 0 0 -0 0</acceleration>
          <wrench>0 0 0 0 -0 0</wrench>
        </link>
      </model>
      <model name='plant_4A'>
        <pose>2 3 0 0 -0 0</pose>
        <scale>1 1 1</scale>
        <link name='link'>
          <pose>2 3 0 0 -0 0</pose>
          <velocity>0 0 0 0 -0 0</velocity>
          <acceleration>0 0 0 0 -0 0</acceleration>
          <wrench>0 0 0 0 -0 0</wrench>
        </link>
      </model>
      <model name='plant_4B'>
        <pose>2.667 3 0 0 -0 0</pose>
        <scale>1 1 1</scale>
        <link name='link'>
          <pose>2.667 3 0 0 -0 0</pose>
          <velocity>0 0 0 0 -0 0</velocity>
          <acceleration>0 0 0 0 -0 0</acceleration>
          <wrench>0 0 0 0 -0 0</wrench>
        </link>
      </model>
      <model name='plant_4C'>
        <pose>3.333 3 0 0 -0 0</pose>
        <scale>1 1 1</scale>
        <link name='link'>
          <pose>3.333 3 0 0 -0 0</pose>
          <velocity>0 0 0 0 -0 0</velocity>
          <acceleration>0 0 0 0 -0 0</acceleration>
          <wrench>0 0 0 0 -0 0</wrench>
        </link>
      </model>
      <model name='plant_4D'>
        <pose>4 3 0 0 -0 0</pose>
        <scale>1 1 1</scale>
        <link name='link'>
          <pose>4 3 0 0 -0 0</pose>
          <velocity>0 0 0 0 -0 0</velocity>
          <acceleration>0 0 0 0 -0 0</acceleration>
          <wrench>0 0 0 0 -0 0</wrench>
        </link>
      </model>
      <model name='robot1'>
        <pose>-8.51252 3.0034 0.269657 6.1e-05 -1e-05 -0.001574</pose>
        <scale>1 1 1</scale>
        <link name='base_link'>
          <pose>-8.58824 3.00352 0.357156 6.1e-05 -1e-05 -0.001574</pose>
          <velocity>-0.00154 -0.002306 -0.013705 0.014413 0.011178 0.000484</velocity>
          <acceleration>-0.001562 0.008675 -9.80115 -0.004174 0.001012 0.001995</acceleration>
          <wrench>-0.001787 0.009924 -11.212 0 -0 0</wrench>
        </link>
        <link name='caster'>
          <pose>-8.99109 3.00416 0.207152 -0.002519 -0.284581 0.009141</pose>
          <velocity>-0.003341 -0.000345 -0.0092 0.003488 -0.020917 0.000303</velocity>
          <acceleration>0.029244 0.008821 -9.79899 0 -0 0</acceleration>
          <wrench>0.029244 0.008821 -9.79899 0 -0 0</wrench>
        </link>
        <link name='hokuyo::link'>
          <pose>-8.11253 3.00274 0.769661 6.1e-05 -1e-05 -0.001574</pose>
          <velocity>0.003072 -0.008015 -0.019027 0.014375 0.011179 0.000476</velocity>
          <acceleration>-0.001429 0.009962 -9.80345 0.005311 0.000711 0.004127</acceleration>
          <wrench>-0.000143 0.000996 -0.980345 0 -0 0</wrench>
        </link>
        <link name='left_wheel'>
          <pose>-8.23489 3.31548 0.257179 -1.57064 -0.037296 -0.001579</pose>
          <velocity>-0.002781 -0.00043 -0.013193 0.014984 0.011177 0.000485</velocity>
          <acceleration>-0.009303 -0.057019 -9.79415 -0.146884 0.001392 0.001586</acceleration>
          <wrench>-0.018606 -0.114039 -19.5883 0 -0 0</wrench>
        </link>
        <link name='right_wheel'>
          <pose>-8.23587 2.69046 0.257141 -1.57064 -0.036722 -0.001579</pose>
          <velocity>-0.002494 -0.000846 -0.022134 0.014106 0.011178 0.000447</velocity>
          <acceleration>-0.004354 0.047149 -9.80552 0.072557 0.001046 0.009724</acceleration>
          <wrench>-0.008709 0.094298 -19.611 0 -0 0</wrench>
        </link>
      </model>
      <model name='robot2'>
        <pose>-8.52484 1.00868 0.269644 -3e-06 -2.3e-05 -0.008738</pose>
        <scale>1 1 1</scale>
        <link name='base_link'>
          <pose>-8.60056 1.00934 0.357143 -3e-06 -2.3e-05 -0.008738</pose>
          <velocity>-0.006174 -0.015109 -0.020817 0.089628 -0.028861 -0.003118</velocity>
          <acceleration>-4.86701 -15.5777 25.3839 0.72598 0.758308 2.00328</acceleration>
          <wrench>-5.56761 -17.8201 29.0379 0 -0 0</wrench>
        </link>
        <link name='caster'>
          <pose>-9.00339 1.01286 0.207133 -0.083135 -0.503871 0.024752</pose>
          <velocity>-0.00207 -0.000581 -0.032032 -0.003084 -0.019544 -6e-05</velocity>
          <acceleration>1.53359 -0.932252 8.55901 -0 -0 -0</acceleration>
          <wrench>1.53359 -0.932252 8.55901 0 -0 0</wrench>
        </link>
        <link name='left_wheel'>
          <pose>-8.24498 1.31876 0.25715 -1.57071 -0.031756 -0.008741</pose>
          <velocity>-0.002755 -0.009984 0.017434 0.084191 -0.018527 -0.003305</velocity>
          <acceleration>0.308538 -10.9982 67.8561 0.756651 0.079954 2.4509</acceleration>
          <wrench>0.617076 -21.9965 135.712 0 -0 0</wrench>
        </link>
        <link name='right_wheel'>
          <pose>-8.25044 0.693754 0.257152 -1.5707 -0.025649 -0.00874</pose>
          <velocity>-0.004334 -0.007477 -0.038964 0.089442 -0.026947 -0.003133</velocity>
          <acceleration>-2.03426 -8.40583 12.706 2.97886 0.311402 -0.544975</acceleration>
          <wrench>-4.06852 -16.8117 25.4119 0 -0 0</wrench>
        </link>
      </model>
      <model name='robot3'>
        <pose>-8.54007 -0.994071 0.269616 -5.8e-05 -4.6e-05 -0.007013</pose>
        <scale>1 1 1</scale>
        <link name='base_link'>
          <pose>-8.61579 -0.993535 0.357112 -5.8e-05 -4.6e-05 -0.007013</pose>
          <velocity>-0.005303 0.010296 -0.019576 -0.053185 -0.012453 0.001267</velocity>
          <acceleration>0.482853 0.539871 -3.73558 0.170103 -0.828136 0.408278</acceleration>
          <wrench>0.241427 0.269936 -1.86779 0 -0 0</wrench>
        </link>
        <link name='caster'>
          <pose>-9.01863 -0.990718 0.207094 -0.094033 -0.550793 0.026941</pose>
          <velocity>-0.003473 0.001698 -0.024757 -0.016779 -0.04561 -6.3e-05</velocity>
          <acceleration>-1.19844 0.129502 0.922272 -1.08393 -1.3601 -3.1e-05</acceleration>
          <wrench>-0.599219 0.064751 0.461136 0 -0 0</wrench>
        </link>
        <link name='left_wheel'>
          <pose>-8.26074 -0.683509 0.257111 -1.57076 -0.003898 -0.007013</pose>
          <velocity>-0.004412 0.005453 -0.031706 -0.053028 -0.012454 0.001268</velocity>
          <acceleration>-0.759549 0.574087 -7.72245 1.06319 1.13274 0.341759</acceleration>
          <wrench>-0.759549 0.574087 -7.72245 0 -0 0</wrench>
        </link>
        <link name='right_wheel'>
          <pose>-8.26513 -1.30852 0.257147 -1.57075 -0.000549 -0.007013</pose>
          <velocity>-0.003556 0.004966 0.001521 -0.054374 -0.012445 0.001232</velocity>
          <acceleration>-0.113247 -1.17964 -8.3759 2.5094 0.426266 0.228173</acceleration>
          <wrench>-0.113247 -1.17964 -8.3759 0 -0 0</wrench>
        </link>
      </model>
      <model name='robot4'>
        <pose>-8.56282 -3.00076 0.269633 8.9e-05 -5.5e-05 -0.011623</pose>
        <scale>1 1 1</scale>
        <link name='base_link'>
          <pose>-8.71425 -2.99902 0.444624 8.9e-05 -5.5e-05 -0.011623</pose>
          <velocity>-0.008377 -0.008651 -0.023365 0.029962 -0.022353 -0.003041</velocity>
          <acceleration>0.008032 0.016829 -9.79917 0.009501 -0.000771 0.001123</acceleration>
          <wrench>0.004594 0.009626 -5.60488 0 -0 0</wrench>
        </link>
        <link name='caster'>
          <pose>-9.04135 -2.99519 0.207106 -0.112261 -0.852409 0.043105</pose>
          <velocity>-0.003081 -0.000593 -0.030553 -0.001431 -0.036518 0.000189</velocity>
          <acceleration>0.016227 0.030623 -9.80142 0 -0 0</acceleration>
          <wrench>0.008114 0.015312 -4.90071 0 -0 0</wrench>
        </link>
        <link name='left_wheel'>
          <pose>-8.28207 -2.69149 0.257176 -1.57061 0.01332 -0.01162</pose>
          <velocity>-0.002968 -0.004114 -0.004549 0.030421 -0.022358 -0.003042</velocity>
          <acceleration>-0.063299 -0.039856 -9.78078 -0.105012 0.000666 0.000717</acceleration>
          <wrench>-0.03165 -0.019928 -4.89039 0 -0 0</wrench>
        </link>
        <link name='right_wheel'>
          <pose>-8.28933 -3.31648 0.25712 -1.57061 0.003345 -0.011622</pose>
          <velocity>-0.005269 -0.004203 -0.02331 0.030156 -0.022355 -0.003035</velocity>
          <acceleration>0.037884 -0.010019 -9.81875 -0.033388 -0.00033 -0.00063</acceleration>
          <wrench>0.018942 -0.005009 -4.90938 0 -0 0</wrench>
        </link>
      </model>
      <model name='well'>
        <pose>-8 8 0 0 -0 0</pose>
        <scale>1 1 1</scale>
        <link name='link'>
          <pose>-8 8 0 0 -0 0</pose>
          <velocity>0 0 0 0 -0 0</velocity>
          <acceleration>0 0 0 0 -0 0</acceleration>
          <wrench>0 0 0 0 -0 0</wrench>
        </link>
      </model>
      <light name='sun'>
        <pose>0 0 5 0 -0 0</pose>
      </light>
      <light name='sun_clone'>
        <pose>13.3913 1.36485 5 0 -0 0</pose>
      </light>
    </state>
    <gui fullscreen='0'>
      <camera name='user_camera'>
        <pose>-25.8383 1.85974 10.5588 0 0.473848 0.010352</pose>
        <view_controller>orbit</view_controller>
        <projection_type>perspective</projection_type>
      </camera>
    </gui>
    <model name='well'>
      <static>1</static>
      <link name='link'>
        <visual name='visual'>
          <geometry>
            <mesh>
              <uri>file:///home/violas/ros2_ws/src/plugins/models/well/meshes/well.dae</uri>
              <scale>0.1 0.1 0.1</scale>
            </mesh>
          </geometry>
        </visual>
        <self_collide>0</self_collide>
        <enable_wind>0</enable_wind>
        <kinematic>0</kinematic>
      </link>
      <pose>-8.48011 6.54444 0 0 -0 0</pose>
    </model>
    <model name='mud'>
      <static>1</static>
      <link name='link'>
        <collision name='collision'>
          <geometry>
            <box>
              <size>17.6 20 0.2</size>
            </box>
          </geometry>
          <max_contacts>10</max_contacts>
          <surface>
            <contact>
              <ode/>
            </contact>
            <bounce/>
            <friction>
              <torsional>
                <ode/>
              </torsional>
              <ode/>
            </friction>
          </surface>
        </collision>
        <visual name='visual_1'>
          <pose>-4.4 5 0 0 -0 0</pose>
          <cast_shadows>0</cast_shadows>
          <geometry>
            <box>
              <size>8.8 10 0.2</size>
            </box>
          </geometry>
          <material>
            <script>
              <uri>model://mud_box/materials/scripts</uri>
              <uri>model://mud_box/materials/textures</uri>
              <name>vrc/mud</name>
            </script>
          </material>
        </visual>
        <visual name='visual_2'>
          <pose>4.4 5 0 0 -0 0</pose>
          <cast_shadows>0</cast_shadows>
          <geometry>
            <box>
              <size>8.8 10 0.2</size>
            </box>
          </geometry>
          <material>
            <script>
              <uri>model://mud_box/materials/scripts</uri>
              <uri>model://mud_box/materials/textures</uri>
              <name>vrc/mud</name>
            </script>
          </material>
        </visual>
        <visual name='visual_3'>
          <pose>4.4 -5 0 0 -0 0</pose>
          <cast_shadows>0</cast_shadows>
          <geometry>
            <box>
              <size>8.8 10 0.2</size>
            </box>
          </geometry>
          <material>
            <script>
              <uri>model://mud_box/materials/scripts</uri>
              <uri>model://mud_box/materials/textures</uri>
              <name>vrc/mud</name>
            </script>
          </material>
        </visual>
        <visual name='visual_4'>
          <pose>-4.4 -5 0 0 -0 0</pose>
          <cast_shadows>0</cast_shadows>
          <geometry>
            <box>
              <size>8.8 10 0.2</size>
            </box>
          </geometry>
          <material>
            <script>
              <uri>model://mud_box/materials/scripts</uri>
              <uri>model://mud_box/materials/textures</uri>
              <name>vrc/mud</name>
            </script>
          </material>
        </visual>
        <self_collide>0</self_collide>
        <enable_wind>0</enable_wind>
        <kinematic>0</kinematic>
      </link>
      <pose>-1.17148 -0.05098 0 0 -0 0</pose>
    </model>
    <model name='charger'>
      <static>1</static>
      <link name='link'>
        <visual name='visual'>
          <geometry>
            <mesh>
              <uri>file:///home/violas/ros2_ws/src/plugins/models/charger2/charger.dae</uri>
              <scale>1 1 1</scale>
            </mesh>
          </geometry>
        </visual>
        <self_collide>0</self_collide>
        <enable_wind>0</enable_wind>
        <kinematic>0</kinematic>
      </link>
      <pose>-8.43554 -7.3173 0 0 -0 0</pose>
    </model>
    <model name='outroBigCilindro'>
      <link name='link'>
        <inertial>
          <mass>1</mass>
          <inertia>
            <ixx>0.145833</ixx>
            <ixy>0</ixy>
            <ixz>0</ixz>
            <iyy>0.145833</iyy>
            <iyz>0</iyz>
            <izz>0.125</izz>
          </inertia>
          <pose>0 0 0 0 -0 0</pose>
        </inertial>
        <self_collide>0</self_collide>
        <enable_wind>0</enable_wind>
        <kinematic>0</kinematic>
        <pose>0 0 0 0 -0 0</pose>
        <gravity>1</gravity>
        <visual name='visual'>
          <geometry>
            <cylinder>
              <radius>1.04919</radius>
              <length>0.0737918</length>
            </cylinder>
          </geometry>
          <material>
            <script>
              <name>Gazebo/Grey</name>
              <uri>file://media/materials/scripts/gazebo.material</uri>
            </script>
            <shader type='pixel'>
              <normal_map>__default__</normal_map>
            </shader>
            <ambient>0.2 0.1 0.1 1</ambient>
            <diffuse>0.2 0.1 0.1 1</diffuse>
            <specular>0.2 0.11 0.11 1</specular>
            <emissive>0.2 0.1 0.1 1</emissive>
          </material>
          <pose>0 0 0 0 -0 0</pose>
          <transparency>0</transparency>
          <cast_shadows>1</cast_shadows>
        </visual>
        <collision name='collision'>
          <laser_retro>0</laser_retro>
          <max_contacts>10</max_contacts>
          <pose>0 0 0 0 -0 0</pose>
          <geometry>
            <cylinder>
              <radius>1.04919</radius>
              <length>0.0737918</length>
            </cylinder>
          </geometry>
          <surface>
            <friction>
              <ode>
                <mu>1</mu>
                <mu2>1</mu2>
                <fdir1>0 0 0</fdir1>
                <slip1>0</slip1>
                <slip2>0</slip2>
              </ode>
              <torsional>
                <coefficient>1</coefficient>
                <patch_radius>0</patch_radius>
                <surface_radius>0</surface_radius>
                <use_patch_radius>1</use_patch_radius>
                <ode>
                  <slip>0</slip>
                </ode>
              </torsional>
            </friction>
            <bounce>
              <restitution_coefficient>0</restitution_coefficient>
              <threshold>1e+06</threshold>
            </bounce>
            <contact>
              <collide_without_contact>0</collide_without_contact>
              <collide_without_contact_bitmask>1</collide_without_contact_bitmask>
              <collide_bitmask>1</collide_bitmask>
              <ode>
                <soft_cfm>0</soft_cfm>
                <soft_erp>0.2</soft_erp>
                <kp>1e+13</kp>
                <kd>1</kd>
                <max_vel>0.01</max_vel>
                <min_depth>0</min_depth>
              </ode>
              <bullet>
                <split_impulse>1</split_impulse>
                <split_impulse_penetration_threshold>-0.01</split_impulse_penetration_threshold>
                <soft_cfm>0</soft_cfm>
                <soft_erp>0.2</soft_erp>
                <kp>1e+13</kp>
                <kd>1</kd>
              </bullet>
            </contact>
          </surface>
        </collision>
      </link>
      <static>0</static>
      <allow_auto_disable>1</allow_auto_disable>
      <pose>-8 6.2 0.19837 4e-06 4e-06 -0</pose>
    </model>
    <light name='sun_clone' type='directional'>
      <pose>13.3913 1.36485 5 0 -0 0</pose>
      <diffuse>0.8 0.8 0.8 1</diffuse>
      <specular>0.2 0.2 0.2 1</specular>
      <direction>-0.483368 0.096674 -0.870063</direction>
      <attenuation>
        <range>1000</range>
        <constant>0.9</constant>
        <linear>0.01</linear>
        <quadratic>0.001</quadratic>
      </attenuation>
      <cast_shadows>1</cast_shadows>
      <spot>
        <inner_angle>0</inner_angle>
        <outer_angle>0</outer_angle>
        <falloff>0</falloff>
      </spot>
    </light>
    <model name='robot1'>
      <pose>-8.06514 3.24018 0.100758 9e-06 -0 0.039965</pose>
      <link name='base_link'>
        <pose>-0.075714 -0 0.0875 0 -0 0</pose>
        <inertial>
          <mass>1.14395</mass>
          <inertia>
            <ixx>0.126164</ixx>
            <ixy>0</ixy>
            <ixz>0</ixz>
            <iyy>0.416519</iyy>
            <iyz>0</iyz>
            <izz>0.481014</izz>
          </inertia>
          <pose>0 0 0 0 -0 0</pose>
        </inertial>
        <visual name='visual'>
          <geometry>
            <box>
              <size>1.00571 0.5 0.284363</size>
            </box>
          </geometry>
          <material>
            <ambient>1 0.6 0.4 1</ambient>
            <diffuse>1 0.6 0.4 1</diffuse>
            <specular>1 0.8 0.6 1</specular>
          </material>
        </visual>
        <collision name='collision'>
          <geometry>
            <box>
              <size>1.00571 0.5 0.284363</size>
            </box>
          </geometry>
          <max_contacts>10</max_contacts>
          <surface>
            <contact>
              <ode/>
            </contact>
            <bounce/>
            <friction>
              <torsional>
                <ode/>
              </torsional>
              <ode/>
            </friction>
          </surface>
        </collision>
        <self_collide>0</self_collide>
        <enable_wind>0</enable_wind>
        <kinematic>0</kinematic>
      </link>
      <link name='left_wheel'>
        <pose>0.277142 0.312515 -0.0125 -1.5707 0 0</pose>
        <inertial>
          <mass>2</mass>
          <inertia>
            <ixx>0.145833</ixx>
            <ixy>0</ixy>
            <ixz>0</ixz>
            <iyy>0.145833</iyy>
            <iyz>0</iyz>
            <izz>0.125</izz>
          </inertia>
          <pose>0 0 0 0 -0 0</pose>
        </inertial>
        <visual name='visual'>
          <geometry>
            <sphere>
              <radius>0.15</radius>
            </sphere>
          </geometry>
          <material>
            <ambient>0.1 0.1 0.1 1</ambient>
            <diffuse>0.2 0.2 0.2 1</diffuse>
            <specular>0.3 0.3 0.3 1</specular>
          </material>
        </visual>
        <collision name='collision'>
          <geometry>
            <sphere>
              <radius>0.15</radius>
            </sphere>
          </geometry>
          <surface>
            <friction>
              <ode>
                <mu>1</mu>
                <mu2>1</mu2>
                <slip1>0</slip1>
                <slip2>0</slip2>
              </ode>
              <torsional>
                <ode/>
              </torsional>
            </friction>
            <contact>
              <ode>
                <soft_cfm>0</soft_cfm>
                <soft_erp>0.2</soft_erp>
                <kp>1e+13</kp>
                <kd>1</kd>
                <max_vel>0.01</max_vel>
                <min_depth>0.01</min_depth>
              </ode>
            </contact>
            <bounce/>
          </surface>
          <max_contacts>10</max_contacts>
        </collision>
        <self_collide>0</self_collide>
        <enable_wind>0</enable_wind>
        <kinematic>0</kinematic>
      </link>
      <link name='right_wheel'>
        <pose>0.277141 -0.312515 -0.0125 -1.5707 0 0</pose>
        <inertial>
          <mass>2</mass>
          <inertia>
            <ixx>0.145833</ixx>
            <ixy>0</ixy>
            <ixz>0</ixz>
            <iyy>0.145833</iyy>
            <iyz>0</iyz>
            <izz>0.125</izz>
          </inertia>
          <pose>0 0 0 0 -0 0</pose>
        </inertial>
        <visual name='visual'>
          <geometry>
            <sphere>
              <radius>0.15</radius>
            </sphere>
          </geometry>
          <material>
            <ambient>0.1 0.1 0.1 1</ambient>
            <diffuse>0.2 0.2 0.2 1</diffuse>
            <specular>0.3 0.3 0.3 1</specular>
          </material>
        </visual>
        <collision name='collision'>
          <geometry>
            <sphere>
              <radius>0.15</radius>
            </sphere>
          </geometry>
          <surface>
            <friction>
              <ode>
                <mu>1</mu>
                <mu2>1</mu2>
                <slip1>0</slip1>
                <slip2>0</slip2>
              </ode>
              <torsional>
                <ode/>
              </torsional>
            </friction>
            <contact>
              <ode>
                <soft_cfm>0</soft_cfm>
                <soft_erp>0.2</soft_erp>
                <kp>1e+13</kp>
                <kd>1</kd>
                <max_vel>0.01</max_vel>
                <min_depth>0.01</min_depth>
              </ode>
            </contact>
            <bounce/>
          </surface>
          <max_contacts>10</max_contacts>
        </collision>
        <self_collide>0</self_collide>
        <enable_wind>0</enable_wind>
        <kinematic>0</kinematic>
      </link>
      <link name='caster'>
        <pose>-0.478569 -0 -0.0625 0 -0 0</pose>
        <inertial>
          <mass>1</mass>
          <inertia>
            <ixx>0.1</ixx>
            <ixy>0</ixy>
            <ixz>0</ixz>
            <iyy>0.1</iyy>
            <iyz>0</iyz>
            <izz>0.1</izz>
          </inertia>
          <pose>0 0 0 0 -0 0</pose>
        </inertial>
        <visual name='visual'>
          <geometry>
            <sphere>
              <radius>0.1</radius>
            </sphere>
          </geometry>
          <material>
            <ambient>0.1 0.1 0.1 1</ambient>
            <diffuse>0.2 0.2 0.2 1</diffuse>
            <specular>0.3 0.3 0.3 1</specular>
          </material>
        </visual>
        <collision name='collision'>
          <geometry>
            <sphere>
              <radius>0.1</radius>
            </sphere>
          </geometry>
          <max_contacts>10</max_contacts>
          <surface>
            <contact>
              <ode/>
            </contact>
            <bounce/>
            <friction>
              <torsional>
                <ode/>
              </torsional>
              <ode/>
            </friction>
          </surface>
        </collision>
        <self_collide>0</self_collide>
        <enable_wind>0</enable_wind>
        <kinematic>0</kinematic>
      </link>
      <joint name='left_wheel_joint' type='revolute'>
        <parent>base_link</parent>
        <child>left_wheel</child>
        <axis>
          <xyz>0 0 1</xyz>
          <limit>
            <lower>-1.79769e+308</lower>
            <upper>1.79769e+308</upper>
          </limit>
          <dynamics>
            <spring_reference>0</spring_reference>
            <spring_stiffness>0</spring_stiffness>
          </dynamics>
        </axis>
      </joint>
      <joint name='right_wheel_joint' type='revolute'>
        <parent>base_link</parent>
        <child>right_wheel</child>
        <axis>
          <xyz>0 0 1</xyz>
          <limit>
            <lower>-1.79769e+308</lower>
            <upper>1.79769e+308</upper>
          </limit>
          <dynamics>
            <spring_reference>0</spring_reference>
            <spring_stiffness>0</spring_stiffness>
          </dynamics>
        </axis>
      </joint>
      <joint name='caster_wheel' type='ball'>
        <parent>base_link</parent>
        <child>caster</child>
      </joint>
      <plugin name='gazebo_ros_diff_drive' filename='libgazebo_ros_diff_drive.so'>
        <ros>
          <namespace>/robot1</namespace>
          <remapping>odom:=odom</remapping>
        </ros>
        <publishOdomTf>1</publishOdomTf>
        <commandTopic>cmd_vel</commandTopic>
        <odometryTopic>odom</odometryTopic>
        <odometrySource>WORLD</odometrySource>
        <publish_odom>1</publish_odom>
        <robotBaseFrame>base_link</robotBaseFrame>
        <left_joint>left_wheel_joint</left_joint>
        <right_joint>right_wheel_joint</right_joint>
      </plugin>
      <frame name='hokuyo::__model__' attached_to='hokuyo::link'>
        <pose relative_to='__model__'>0.4 0 0.5 0 -0 0</pose>
      </frame>
      <link name='hokuyo::link'>
        <inertial>
          <mass>0.1</mass>
          <pose>0 0 0 0 -0 0</pose>
          <inertia>
            <ixx>1</ixx>
            <ixy>0</ixy>
            <ixz>0</ixz>
            <iyy>1</iyy>
            <iyz>0</iyz>
            <izz>1</izz>
          </inertia>
        </inertial>
        <visual name='visual'>
          <geometry>
            <mesh>
              <uri>model://hokuyo/meshes/hokuyo.dae</uri>
            </mesh>
          </geometry>
        </visual>
        <collision name='collision-base'>
          <pose>0 0 -0.0145 0 -0 0</pose>
          <geometry>
            <box>
              <size>0.05 0.05 0.041</size>
            </box>
          </geometry>
          <max_contacts>10</max_contacts>
          <surface>
            <contact>
              <ode/>
            </contact>
            <bounce/>
            <friction>
              <torsional>
                <ode/>
              </torsional>
              <ode/>
            </friction>
          </surface>
        </collision>
        <collision name='collision-top'>
          <pose>0 0 0.0205 0 -0 0</pose>
          <geometry>
            <cylinder>
              <radius>0.021</radius>
              <length>0.029</length>
            </cylinder>
          </geometry>
          <max_contacts>10</max_contacts>
          <surface>
            <contact>
              <ode/>
            </contact>
            <bounce/>
            <friction>
              <torsional>
                <ode/>
              </torsional>
              <ode/>
            </friction>
          </surface>
        </collision>
        <sensor name='laser' type='ray'>
          <pose>0.01 0 0.0175 0 -0 0</pose>
          <ray>
            <scan>
              <horizontal>
                <samples>640</samples>
                <resolution>1</resolution>
                <min_angle>-2.26889</min_angle>
                <max_angle>2.2689</max_angle>
              </horizontal>
              <vertical>
                <samples>1</samples>
                <min_angle>0</min_angle>
                <max_angle>0</max_angle>
              </vertical>
            </scan>
            <range>
              <min>0.08</min>
              <max>10</max>
              <resolution>0.01</resolution>
            </range>
          </ray>
          <plugin name='laser' filename='libgazebo_ros_ray_sensor.so'/>
          <always_on>1</always_on>
          <update_rate>30</update_rate>
          <visualize>1</visualize>
        </sensor>
        <pose relative_to='hokuyo::__model__'>0 0 0 0 -0 0</pose>
        <self_collide>0</self_collide>
        <enable_wind>0</enable_wind>
        <kinematic>0</kinematic>
      </link>
      <joint name='hokuyo_joint' type='fixed'>
        <child>hokuyo::link</child>
        <parent>base_link</parent>
      </joint>
    </model>
    <model name='robot2'>
      <pose>-8.20819 1.06742 0.100758 9e-06 0 0.012346</pose>
      <link name='base_link'>
        <pose>-0.075714 -0 0.0875 0 -0 0</pose>
        <inertial>
          <mass>1.14395</mass>
          <inertia>
            <ixx>0.126164</ixx>
            <ixy>0</ixy>
            <ixz>0</ixz>
            <iyy>0.416519</iyy>
            <iyz>0</iyz>
            <izz>0.481014</izz>
          </inertia>
          <pose>0 0 0 0 -0 0</pose>
        </inertial>
        <visual name='visual'>
          <geometry>
            <box>
              <size>1.00571 0.5 0.284363</size>
            </box>
          </geometry>
          <material>
            <ambient>1 0.75 0.8 1</ambient>
            <diffuse>1 0.75 0.8 1</diffuse>
            <specular>1 0.8 0.8 1</specular>
          </material>
        </visual>
        <collision name='collision'>
          <geometry>
            <box>
              <size>1.00571 0.5 0.284363</size>
            </box>
          </geometry>
          <max_contacts>10</max_contacts>
          <surface>
            <contact>
              <ode/>
            </contact>
            <bounce/>
            <friction>
              <torsional>
                <ode/>
              </torsional>
              <ode/>
            </friction>
          </surface>
        </collision>
        <self_collide>0</self_collide>
        <enable_wind>0</enable_wind>
        <kinematic>0</kinematic>
      </link>
      <link name='left_wheel'>
        <pose>0.277142 0.312515 -0.0125 -1.5707 0 0</pose>
        <inertial>
          <mass>2</mass>
          <inertia>
            <ixx>0.145833</ixx>
            <ixy>0</ixy>
            <ixz>0</ixz>
            <iyy>0.145833</iyy>
            <iyz>0</iyz>
            <izz>0.125</izz>
          </inertia>
          <pose>0 0 0 0 -0 0</pose>
        </inertial>
        <visual name='visual'>
          <geometry>
            <sphere>
              <radius>0.15</radius>
            </sphere>
          </geometry>
          <material>
            <ambient>0.1 0.1 0.1 1</ambient>
            <diffuse>0.2 0.2 0.2 1</diffuse>
            <specular>0.3 0.3 0.3 1</specular>
          </material>
        </visual>
        <collision name='collision'>
          <geometry>
            <sphere>
              <radius>0.15</radius>
            </sphere>
          </geometry>
          <surface>
            <friction>
              <ode>
                <mu>1</mu>
                <mu2>1</mu2>
                <slip1>0</slip1>
                <slip2>0</slip2>
              </ode>
              <torsional>
                <ode/>
              </torsional>
            </friction>
            <contact>
              <ode>
                <soft_cfm>0</soft_cfm>
                <soft_erp>0.2</soft_erp>
                <kp>1e+13</kp>
                <kd>1</kd>
                <max_vel>0.01</max_vel>
                <min_depth>0.01</min_depth>
              </ode>
            </contact>
            <bounce/>
          </surface>
          <max_contacts>10</max_contacts>
        </collision>
        <self_collide>0</self_collide>
        <enable_wind>0</enable_wind>
        <kinematic>0</kinematic>
      </link>
      <link name='right_wheel'>
        <pose>0.277141 -0.312515 -0.0125 -1.5707 0 0</pose>
        <inertial>
          <mass>2</mass>
          <inertia>
            <ixx>0.145833</ixx>
            <ixy>0</ixy>
            <ixz>0</ixz>
            <iyy>0.145833</iyy>
            <iyz>0</iyz>
            <izz>0.125</izz>
          </inertia>
          <pose>0 0 0 0 -0 0</pose>
        </inertial>
        <visual name='visual'>
          <geometry>
            <sphere>
              <radius>0.15</radius>
            </sphere>
          </geometry>
          <material>
            <ambient>0.1 0.1 0.1 1</ambient>
            <diffuse>0.2 0.2 0.2 1</diffuse>
            <specular>0.3 0.3 0.3 1</specular>
          </material>
        </visual>
        <collision name='collision'>
          <geometry>
            <sphere>
              <radius>0.15</radius>
            </sphere>
          </geometry>
          <surface>
            <friction>
              <ode>
                <mu>1</mu>
                <mu2>1</mu2>
                <slip1>0</slip1>
                <slip2>0</slip2>
              </ode>
              <torsional>
                <ode/>
              </torsional>
            </friction>
            <contact>
              <ode>
                <soft_cfm>0</soft_cfm>
                <soft_erp>0.2</soft_erp>
                <kp>1e+13</kp>
                <kd>1</kd>
                <max_vel>0.01</max_vel>
                <min_depth>0.01</min_depth>
              </ode>
            </contact>
            <bounce/>
          </surface>
          <max_contacts>10</max_contacts>
        </collision>
        <self_collide>0</self_collide>
        <enable_wind>0</enable_wind>
        <kinematic>0</kinematic>
      </link>
      <link name='caster'>
        <pose>-0.478569 -0 -0.0625 0 -0 0</pose>
        <inertial>
          <mass>1</mass>
          <inertia>
            <ixx>0.1</ixx>
            <ixy>0</ixy>
            <ixz>0</ixz>
            <iyy>0.1</iyy>
            <iyz>0</iyz>
            <izz>0.1</izz>
          </inertia>
          <pose>0 0 0 0 -0 0</pose>
        </inertial>
        <visual name='visual'>
          <geometry>
            <sphere>
              <radius>0.1</radius>
            </sphere>
          </geometry>
          <material>
            <ambient>0.1 0.1 0.1 1</ambient>
            <diffuse>0.2 0.2 0.2 1</diffuse>
            <specular>0.3 0.3 0.3 1</specular>
          </material>
        </visual>
        <collision name='collision'>
          <geometry>
            <sphere>
              <radius>0.1</radius>
            </sphere>
          </geometry>
          <max_contacts>10</max_contacts>
          <surface>
            <contact>
              <ode/>
            </contact>
            <bounce/>
            <friction>
              <torsional>
                <ode/>
              </torsional>
              <ode/>
            </friction>
          </surface>
        </collision>
        <self_collide>0</self_collide>
        <enable_wind>0</enable_wind>
        <kinematic>0</kinematic>
      </link>
      <joint name='left_wheel_joint' type='revolute'>
        <parent>base_link</parent>
        <child>left_wheel</child>
        <axis>
          <xyz>0 0 1</xyz>
          <limit>
            <lower>-1.79769e+308</lower>
            <upper>1.79769e+308</upper>
          </limit>
          <dynamics>
            <spring_reference>0</spring_reference>
            <spring_stiffness>0</spring_stiffness>
          </dynamics>
        </axis>
      </joint>
      <joint name='right_wheel_joint' type='revolute'>
        <parent>base_link</parent>
        <child>right_wheel</child>
        <axis>
          <xyz>0 0 1</xyz>
          <limit>
            <lower>-1.79769e+308</lower>
            <upper>1.79769e+308</upper>
          </limit>
          <dynamics>
            <spring_reference>0</spring_reference>
            <spring_stiffness>0</spring_stiffness>
          </dynamics>
        </axis>
      </joint>
      <joint name='caster_wheel' type='ball'>
        <parent>base_link</parent>
        <child>caster</child>
      </joint>
      <plugin name='gazebo_ros_diff_drive' filename='libgazebo_ros_diff_drive.so'>
        <ros>
          <namespace>/robot2</namespace>
          <remapping>odom:=odom</remapping>
        </ros>
        <publishOdomTf>1</publishOdomTf>
        <commandTopic>cmd_vel</commandTopic>
        <odometryTopic>odom</odometryTopic>
        <odometrySource>WORLD</odometrySource>
        <publish_odom>1</publish_odom>
        <robotBaseFrame>base_link</robotBaseFrame>
        <left_joint>left_wheel_joint</left_joint>
        <right_joint>right_wheel_joint</right_joint>
      </plugin>
    </model>
    <model name='robot3'>
      <pose>-8.23759 -1.21494 0.201518 0 -0 0.021201</pose>
      <link name='base_link'>
        <pose>-0.075714 -0 0.0875 0 -0 0</pose>
        <inertial>
          <mass>0.5</mass>
          <inertia>
            <ixx>0.01577</ixx>
            <ixy>0</ixy>
            <ixz>0</ixz>
            <iyy>0.20826</iyy>
            <iyz>0</iyz>
            <izz>0.24051</izz>
          </inertia>
          <pose>0 0 0 0 -0 0</pose>
        </inertial>
        <visual name='visual'>
          <geometry>
            <box>
              <size>1.00571 0.5 0.284363</size>
            </box>
          </geometry>
          <material>
            <ambient>0.54 0.81 0.94 1</ambient>
            <diffuse>0.54 0.81 0.94 1</diffuse>
            <specular>0.6 0.9 1 1</specular>
          </material>
        </visual>
        <collision name='collision'>
          <geometry>
            <box>
              <size>1.00571 0.5 0.284363</size>
            </box>
          </geometry>
          <max_contacts>10</max_contacts>
          <surface>
            <contact>
              <ode/>
            </contact>
            <bounce/>
            <friction>
              <torsional>
                <ode/>
              </torsional>
              <ode/>
            </friction>
          </surface>
        </collision>
        <self_collide>0</self_collide>
        <enable_wind>0</enable_wind>
        <kinematic>0</kinematic>
      </link>
      <link name='left_wheel'>
        <pose>0.277142 0.312514 -0.0125 -1.5707 0 0</pose>
        <inertial>
          <mass>1</mass>
          <inertia>
            <ixx>0.0729165</ixx>
            <ixy>0</ixy>
            <ixz>0</ixz>
            <iyy>0.0729165</iyy>
            <iyz>0</iyz>
            <izz>0.0625</izz>
          </inertia>
          <pose>0 0 0 0 -0 0</pose>
        </inertial>
        <visual name='visual'>
          <geometry>
            <sphere>
              <radius>0.15</radius>
            </sphere>
          </geometry>
          <material>
            <ambient>0.1 0.1 0.1 1</ambient>
            <diffuse>0.2 0.2 0.2 1</diffuse>
            <specular>0.3 0.3 0.3 1</specular>
          </material>
        </visual>
        <collision name='collision'>
          <geometry>
            <sphere>
              <radius>0.15</radius>
            </sphere>
          </geometry>
          <surface>
            <friction>
              <ode>
                <mu>1</mu>
                <mu2>1</mu2>
                <slip1>0</slip1>
                <slip2>0</slip2>
              </ode>
              <torsional>
                <ode/>
              </torsional>
            </friction>
            <contact>
              <ode>
                <soft_cfm>0</soft_cfm>
                <soft_erp>0.2</soft_erp>
                <kp>1e+13</kp>
                <kd>1</kd>
                <max_vel>0.01</max_vel>
                <min_depth>0.01</min_depth>
              </ode>
            </contact>
            <bounce/>
          </surface>
          <max_contacts>10</max_contacts>
        </collision>
        <self_collide>0</self_collide>
        <enable_wind>0</enable_wind>
        <kinematic>0</kinematic>
      </link>
      <link name='right_wheel'>
        <pose>0.277141 -0.312514 -0.0125 -1.5707 0 0</pose>
        <inertial>
          <mass>1</mass>
          <inertia>
            <ixx>0.0729165</ixx>
            <ixy>0</ixy>
            <ixz>0</ixz>
            <iyy>0.0729165</iyy>
            <iyz>0</iyz>
            <izz>0.0625</izz>
          </inertia>
          <pose>0 0 0 0 -0 0</pose>
        </inertial>
        <visual name='visual'>
          <geometry>
            <sphere>
              <radius>0.15</radius>
            </sphere>
          </geometry>
          <material>
            <ambient>0.1 0.1 0.1 1</ambient>
            <diffuse>0.2 0.2 0.2 1</diffuse>
            <specular>0.3 0.3 0.3 1</specular>
          </material>
        </visual>
        <collision name='collision'>
          <geometry>
            <sphere>
              <radius>0.15</radius>
            </sphere>
          </geometry>
          <surface>
            <friction>
              <ode>
                <mu>1</mu>
                <mu2>1</mu2>
                <slip1>0</slip1>
                <slip2>0</slip2>
              </ode>
              <torsional>
                <ode/>
              </torsional>
            </friction>
            <contact>
              <ode>
                <soft_cfm>0</soft_cfm>
                <soft_erp>0.2</soft_erp>
                <kp>1e+13</kp>
                <kd>1</kd>
                <max_vel>0.01</max_vel>
                <min_depth>0.01</min_depth>
              </ode>
            </contact>
            <bounce/>
          </surface>
          <max_contacts>10</max_contacts>
        </collision>
        <self_collide>0</self_collide>
        <enable_wind>0</enable_wind>
        <kinematic>0</kinematic>
      </link>
      <link name='caster'>
        <pose>-0.478569 -0 -0.0625 0 -0 0</pose>
        <inertial>
          <mass>0.5</mass>
          <inertia>
            <ixx>0.025</ixx>
            <ixy>0</ixy>
            <ixz>0</ixz>
            <iyy>0.025</iyy>
            <iyz>0</iyz>
            <izz>0.025</izz>
          </inertia>
          <pose>0 0 0 0 -0 0</pose>
        </inertial>
        <visual name='visual'>
          <geometry>
            <sphere>
              <radius>0.1</radius>
            </sphere>
          </geometry>
          <material>
            <ambient>0.1 0.1 0.1 1</ambient>
            <diffuse>0.2 0.2 0.2 1</diffuse>
            <specular>0.3 0.3 0.3 1</specular>
          </material>
        </visual>
        <collision name='collision'>
          <geometry>
            <sphere>
              <radius>0.1</radius>
            </sphere>
          </geometry>
          <max_contacts>10</max_contacts>
          <surface>
            <contact>
              <ode/>
            </contact>
            <bounce/>
            <friction>
              <torsional>
                <ode/>
              </torsional>
              <ode/>
            </friction>
          </surface>
        </collision>
        <self_collide>0</self_collide>
        <enable_wind>0</enable_wind>
        <kinematic>0</kinematic>
      </link>
      <joint name='left_wheel_joint' type='revolute'>
        <parent>base_link</parent>
        <child>left_wheel</child>
        <axis>
          <xyz>0 0 1</xyz>
          <limit>
            <lower>-1.79769e+308</lower>
            <upper>1.79769e+308</upper>
          </limit>
          <dynamics>
            <spring_reference>0</spring_reference>
            <spring_stiffness>0</spring_stiffness>
          </dynamics>
        </axis>
      </joint>
      <joint name='right_wheel_joint' type='revolute'>
        <parent>base_link</parent>
        <child>right_wheel</child>
        <axis>
          <xyz>0 0 1</xyz>
          <limit>
            <lower>-1.79769e+308</lower>
            <upper>1.79769e+308</upper>
          </limit>
          <dynamics>
            <spring_reference>0</spring_reference>
            <spring_stiffness>0</spring_stiffness>
          </dynamics>
        </axis>
      </joint>
      <joint name='caster_wheel' type='ball'>
        <parent>base_link</parent>
        <child>caster</child>
      </joint>
      <plugin name='gazebo_ros_diff_drive' filename='libgazebo_ros_diff_drive.so'>
        <ros>
          <namespace>/robot3</namespace>
          <remapping>odom:=odom</remapping>
        </ros>
        <publishOdomTf>1</publishOdomTf>
        <commandTopic>cmd_vel</commandTopic>
        <odometryTopic>odom</odometryTopic>
        <odometrySource>WORLD</odometrySource>
        <publish_odom>1</publish_odom>
        <robotBaseFrame>base_link</robotBaseFrame>
        <left_joint>left_wheel_joint</left_joint>
        <right_joint>right_wheel_joint</right_joint>
      </plugin>
    </model>
    <model name='robot4'>
      <pose>-8.21581 -2.81322 0.201518 0 0 -0.000819</pose>
      <link name='base_link'>
        <pose>-0.151427 -0 0.175 0 -0 0</pose>
        <inertial>
          <mass>0.571975</mass>
          <inertia>
            <ixx>0.015791</ixx>
            <ixy>0</ixy>
            <ixz>0</ixz>
            <iyy>0.20826</iyy>
            <iyz>0</iyz>
            <izz>0.240507</izz>
          </inertia>
          <pose>0 0 0 0 -0 0</pose>
        </inertial>
        <visual name='visual'>
          <geometry>
            <box>
              <size>1.00571 0.5 0.284363</size>
            </box>
          </geometry>
          <material>
            <ambient>0.6 1 0.6 1</ambient>
            <diffuse>0.6 1 0.6 1</diffuse>
            <specular>0.8 1 0.8 1</specular>
          </material>
        </visual>
        <collision name='collision'>
          <geometry>
            <box>
              <size>1.00571 0.5 0.284363</size>
            </box>
          </geometry>
          <max_contacts>10</max_contacts>
          <surface>
            <contact>
              <ode/>
            </contact>
            <bounce/>
            <friction>
              <torsional>
                <ode/>
              </torsional>
              <ode/>
            </friction>
          </surface>
        </collision>
        <self_collide>0</self_collide>
        <enable_wind>0</enable_wind>
        <kinematic>0</kinematic>
      </link>
      <link name='left_wheel'>
        <pose>0.277141 0.312515 -0.0125 -1.5707 0 0</pose>
        <inertial>
          <mass>0.5</mass>
          <inertia>
            <ixx>0.0364583</ixx>
            <ixy>0</ixy>
            <ixz>0</ixz>
            <iyy>0.0364583</iyy>
            <iyz>0</iyz>
            <izz>0.03125</izz>
          </inertia>
          <pose>0 0 0 0 -0 0</pose>
        </inertial>
        <visual name='visual'>
          <geometry>
            <sphere>
              <radius>0.15</radius>
            </sphere>
          </geometry>
          <material>
            <ambient>0.1 0.1 0.1 1</ambient>
            <diffuse>0.2 0.2 0.2 1</diffuse>
            <specular>0.3 0.3 0.3 1</specular>
          </material>
        </visual>
        <collision name='collision'>
          <geometry>
            <sphere>
              <radius>0.15</radius>
            </sphere>
          </geometry>
          <surface>
            <friction>
              <ode>
                <mu>1</mu>
                <mu2>1</mu2>
                <slip1>0</slip1>
                <slip2>0</slip2>
              </ode>
              <torsional>
                <ode/>
              </torsional>
            </friction>
            <contact>
              <ode>
                <soft_cfm>0</soft_cfm>
                <soft_erp>0.2</soft_erp>
                <kp>1e+13</kp>
                <kd>1</kd>
                <max_vel>0.01</max_vel>
                <min_depth>0.01</min_depth>
              </ode>
            </contact>
            <bounce/>
          </surface>
          <max_contacts>10</max_contacts>
        </collision>
        <self_collide>0</self_collide>
        <enable_wind>0</enable_wind>
        <kinematic>0</kinematic>
      </link>
      <link name='right_wheel'>
        <pose>0.277141 -0.312515 -0.0125 -1.5707 0 0</pose>
        <inertial>
          <mass>0.5</mass>
          <inertia>
            <ixx>0.0364583</ixx>
            <ixy>0</ixy>
            <ixz>0</ixz>
            <iyy>0.0364583</iyy>
            <iyz>0</iyz>
            <izz>0.03125</izz>
          </inertia>
          <pose>0 0 0 0 -0 0</pose>
        </inertial>
        <visual name='visual'>
          <geometry>
            <sphere>
              <radius>0.15</radius>
            </sphere>
          </geometry>
          <material>
            <ambient>0.1 0.1 0.1 1</ambient>
            <diffuse>0.2 0.2 0.2 1</diffuse>
            <specular>0.3 0.3 0.3 1</specular>
          </material>
        </visual>
        <collision name='collision'>
          <geometry>
            <sphere>
              <radius>0.15</radius>
            </sphere>
          </geometry>
          <surface>
            <friction>
              <ode>
                <mu>1</mu>
                <mu2>1</mu2>
                <slip1>0</slip1>
                <slip2>0</slip2>
              </ode>
              <torsional>
                <ode/>
              </torsional>
            </friction>
            <contact>
              <ode>
                <soft_cfm>0</soft_cfm>
                <soft_erp>0.2</soft_erp>
                <kp>1e+13</kp>
                <kd>1</kd>
                <max_vel>0.01</max_vel>
                <min_depth>0.01</min_depth>
              </ode>
            </contact>
            <bounce/>
          </surface>
          <max_contacts>10</max_contacts>
        </collision>
        <self_collide>0</self_collide>
        <enable_wind>0</enable_wind>
        <kinematic>0</kinematic>
      </link>
      <link name='caster'>
        <pose>-0.478569 -0 -0.0625 0 -0 0</pose>
        <inertial>
          <mass>0.5</mass>
          <inertia>
            <ixx>0.025</ixx>
            <ixy>0</ixy>
            <ixz>0</ixz>
            <iyy>0.025</iyy>
            <iyz>0</iyz>
            <izz>0.025</izz>
          </inertia>
          <pose>0 0 0 0 -0 0</pose>
        </inertial>
        <visual name='visual'>
          <geometry>
            <sphere>
              <radius>0.1</radius>
            </sphere>
          </geometry>
          <material>
            <ambient>0.1 0.1 0.1 1</ambient>
            <diffuse>0.2 0.2 0.2 1</diffuse>
            <specular>0.3 0.3 0.3 1</specular>
          </material>
        </visual>
        <collision name='collision'>
          <geometry>
            <sphere>
              <radius>0.1</radius>
            </sphere>
          </geometry>
          <max_contacts>10</max_contacts>
          <surface>
            <contact>
              <ode/>
            </contact>
            <bounce/>
            <friction>
              <torsional>
                <ode/>
              </torsional>
              <ode/>
            </friction>
          </surface>
        </collision>
        <self_collide>0</self_collide>
        <enable_wind>0</enable_wind>
        <kinematic>0</kinematic>
      </link>
      <joint name='left_wheel_joint' type='revolute'>
        <parent>base_link</parent>
        <child>left_wheel</child>
        <axis>
          <xyz>0 0 1</xyz>
          <limit>
            <lower>-1.79769e+308</lower>
            <upper>1.79769e+308</upper>
          </limit>
          <dynamics>
            <spring_reference>0</spring_reference>
            <spring_stiffness>0</spring_stiffness>
          </dynamics>
        </axis>
      </joint>
      <joint name='right_wheel_joint' type='revolute'>
        <parent>base_link</parent>
        <child>right_wheel</child>
        <axis>
          <xyz>0 0 1</xyz>
          <limit>
            <lower>-1.79769e+308</lower>
            <upper>1.79769e+308</upper>
          </limit>
          <dynamics>
            <spring_reference>0</spring_reference>
            <spring_stiffness>0</spring_stiffness>
          </dynamics>
        </axis>
      </joint>
      <joint name='caster_wheel' type='ball'>
        <parent>base_link</parent>
        <child>caster</child>
      </joint>
      <plugin name='gazebo_ros_diff_drive' filename='libgazebo_ros_diff_drive.so'>
        <ros>
          <namespace>/robot4</namespace>
          <remapping>odom:=odom</remapping>
        </ros>
        <publishOdomTf>1</publishOdomTf>
        <commandTopic>cmd_vel</commandTopic>
        <odometryTopic>odom</odometryTopic>
        <odometrySource>WORLD</odometrySource>
        <publish_odom>1</publish_odom>
        <robotBaseFrame>base_link</robotBaseFrame>
        <left_joint>left_wheel_joint</left_joint>
        <right_joint>right_wheel_joint</right_joint>
      </plugin>
    </model>
    <model name='outroBigCilindro_clone'>
      <link name='link'>
        <inertial>
          <mass>1</mass>
          <inertia>
            <ixx>0.145833</ixx>
            <ixy>0</ixy>
            <ixz>0</ixz>
            <iyy>0.145833</iyy>
            <iyz>0</iyz>
            <izz>0.125</izz>
          </inertia>
          <pose>0 0 0 0 -0 0</pose>
        </inertial>
        <self_collide>0</self_collide>
        <enable_wind>0</enable_wind>
        <kinematic>0</kinematic>
        <pose>0 0 0 0 -0 0</pose>
        <gravity>1</gravity>
        <visual name='visual'>
          <geometry>
            <cylinder>
              <radius>1.04919</radius>
              <length>0.00712547</length>
            </cylinder>
          </geometry>
          <material>
            <script>
              <name>Gazebo/Grey</name>
              <uri>file://media/materials/scripts/gazebo.material</uri>
            </script>
            <shader type='pixel'>
              <normal_map>__default__</normal_map>
            </shader>
            <ambient>0.2 0.1 0.1 1</ambient>
            <diffuse>0.2 0.1 0.1 1</diffuse>
            <specular>0.2 0.11 0.11 1</specular>
            <emissive>0.2 0.1 0.1 1</emissive>
          </material>
          <pose>0 0 0 0 -0 0</pose>
          <transparency>0</transparency>
          <cast_shadows>1</cast_shadows>
        </visual>
        <collision name='collision'>
          <laser_retro>0</laser_retro>
          <max_contacts>10</max_contacts>
          <pose>0 0 0 0 -0 0</pose>
          <geometry>
            <cylinder>
              <radius>1.04919</radius>
              <length>0.00712547</length>
            </cylinder>
          </geometry>
          <surface>
            <friction>
              <ode>
                <mu>1</mu>
                <mu2>1</mu2>
                <fdir1>0 0 0</fdir1>
                <slip1>0</slip1>
                <slip2>0</slip2>
              </ode>
              <torsional>
                <coefficient>1</coefficient>
                <patch_radius>0</patch_radius>
                <surface_radius>0</surface_radius>
                <use_patch_radius>1</use_patch_radius>
                <ode>
                  <slip>0</slip>
                </ode>
              </torsional>
            </friction>
            <bounce>
              <restitution_coefficient>0</restitution_coefficient>
              <threshold>1e+06</threshold>
            </bounce>
            <contact>
              <collide_without_contact>0</collide_without_contact>
              <collide_without_contact_bitmask>1</collide_without_contact_bitmask>
              <collide_bitmask>1</collide_bitmask>
              <ode>
                <soft_cfm>0</soft_cfm>
                <soft_erp>0.2</soft_erp>
                <kp>1e+13</kp>
                <kd>1</kd>
                <max_vel>0.01</max_vel>
                <min_depth>0</min_depth>
              </ode>
              <bullet>
                <split_impulse>1</split_impulse>
                <split_impulse_penetration_threshold>-0.01</split_impulse_penetration_threshold>
                <soft_cfm>0</soft_cfm>
                <soft_erp>0.2</soft_erp>
                <kp>1e+13</kp>
                <kd>1</kd>
              </bullet>
            </contact>
          </surface>
        </collision>
      </link>
      <static>0</static>
      <allow_auto_disable>1</allow_auto_disable>
      <pose>-5.73371 5.79179 0.103563 0 0 -1.2e-05</pose>
    </model>
    <model name='outroBigCilindro_clone_0'>
      <link name='link'>
        <inertial>
          <mass>1</mass>
          <inertia>
            <ixx>0.145833</ixx>
            <ixy>0</ixy>
            <ixz>0</ixz>
            <iyy>0.145833</iyy>
            <iyz>0</iyz>
            <izz>0.125</izz>
          </inertia>
          <pose>0 0 0 0 -0 0</pose>
        </inertial>
        <self_collide>0</self_collide>
        <enable_wind>0</enable_wind>
        <kinematic>0</kinematic>
        <pose>0 0 0 0 -0 0</pose>
        <gravity>1</gravity>
        <visual name='visual'>
          <geometry>
            <cylinder>
              <radius>1.04919</radius>
              <length>0.00712547</length>
            </cylinder>
          </geometry>
          <material>
            <script>
              <name>Gazebo/Grey</name>
              <uri>file://media/materials/scripts/gazebo.material</uri>
            </script>
            <shader type='pixel'>
              <normal_map>__default__</normal_map>
            </shader>
            <ambient>0.2 0.1 0.1 1</ambient>
            <diffuse>0.2 0.1 0.1 1</diffuse>
            <specular>0.2 0.11 0.11 1</specular>
            <emissive>0.2 0.1 0.1 1</emissive>
          </material>
          <pose>0 0 0 0 -0 0</pose>
          <transparency>0</transparency>
          <cast_shadows>1</cast_shadows>
        </visual>
        <collision name='collision'>
          <laser_retro>0</laser_retro>
          <max_contacts>10</max_contacts>
          <pose>0 0 0 0 -0 0</pose>
          <geometry>
            <cylinder>
              <radius>1.04919</radius>
              <length>0.00712547</length>
            </cylinder>
          </geometry>
          <surface>
            <friction>
              <ode>
                <mu>1</mu>
                <mu2>1</mu2>
                <fdir1>0 0 0</fdir1>
                <slip1>0</slip1>
                <slip2>0</slip2>
              </ode>
              <torsional>
                <coefficient>1</coefficient>
                <patch_radius>0</patch_radius>
                <surface_radius>0</surface_radius>
                <use_patch_radius>1</use_patch_radius>
                <ode>
                  <slip>0</slip>
                </ode>
              </torsional>
            </friction>
            <bounce>
              <restitution_coefficient>0</restitution_coefficient>
              <threshold>1e+06</threshold>
            </bounce>
            <contact>
              <collide_without_contact>0</collide_without_contact>
              <collide_without_contact_bitmask>1</collide_without_contact_bitmask>
              <collide_bitmask>1</collide_bitmask>
              <ode>
                <soft_cfm>0</soft_cfm>
                <soft_erp>0.2</soft_erp>
                <kp>1e+13</kp>
                <kd>1</kd>
                <max_vel>0.01</max_vel>
                <min_depth>0</min_depth>
              </ode>
              <bullet>
                <split_impulse>1</split_impulse>
                <split_impulse_penetration_threshold>-0.01</split_impulse_penetration_threshold>
                <soft_cfm>0</soft_cfm>
                <soft_erp>0.2</soft_erp>
                <kp>1e+13</kp>
                <kd>1</kd>
              </bullet>
            </contact>
          </surface>
        </collision>
      </link>
      <static>0</static>
      <allow_auto_disable>1</allow_auto_disable>
      <pose>-5.47532 2.90427 0.103563 0 0 -1.2e-05</pose>
    </model>
    <model name='outroBigCilindro_clone_1'>
      <link name='link'>
        <inertial>
          <mass>1</mass>
          <inertia>
            <ixx>0.145833</ixx>
            <ixy>0</ixy>
            <ixz>0</ixz>
            <iyy>0.145833</iyy>
            <iyz>0</iyz>
            <izz>0.125</izz>
          </inertia>
          <pose>0 0 0 0 -0 0</pose>
        </inertial>
        <self_collide>0</self_collide>
        <enable_wind>0</enable_wind>
        <kinematic>0</kinematic>
        <pose>0 0 0 0 -0 0</pose>
        <gravity>1</gravity>
        <visual name='visual'>
          <geometry>
            <cylinder>
              <radius>1.04919</radius>
              <length>0.00712547</length>
            </cylinder>
          </geometry>
          <material>
            <script>
              <name>Gazebo/Grey</name>
              <uri>file://media/materials/scripts/gazebo.material</uri>
            </script>
            <shader type='pixel'>
              <normal_map>__default__</normal_map>
            </shader>
            <ambient>0.2 0.1 0.1 1</ambient>
            <diffuse>0.2 0.1 0.1 1</diffuse>
            <specular>0.2 0.11 0.11 1</specular>
            <emissive>0.2 0.1 0.1 1</emissive>
          </material>
          <pose>0 0 0 0 -0 0</pose>
          <transparency>0</transparency>
          <cast_shadows>1</cast_shadows>
        </visual>
        <collision name='collision'>
          <laser_retro>0</laser_retro>
          <max_contacts>10</max_contacts>
          <pose>0 0 0 0 -0 0</pose>
          <geometry>
            <cylinder>
              <radius>1.04919</radius>
              <length>0.00712547</length>
            </cylinder>
          </geometry>
          <surface>
            <friction>
              <ode>
                <mu>1</mu>
                <mu2>1</mu2>
                <fdir1>0 0 0</fdir1>
                <slip1>0</slip1>
                <slip2>0</slip2>
              </ode>
              <torsional>
                <coefficient>1</coefficient>
                <patch_radius>0</patch_radius>
                <surface_radius>0</surface_radius>
                <use_patch_radius>1</use_patch_radius>
                <ode>
                  <slip>0</slip>
                </ode>
              </torsional>
            </friction>
            <bounce>
              <restitution_coefficient>0</restitution_coefficient>
              <threshold>1e+06</threshold>
            </bounce>
            <contact>
              <collide_without_contact>0</collide_without_contact>
              <collide_without_contact_bitmask>1</collide_without_contact_bitmask>
              <collide_bitmask>1</collide_bitmask>
              <ode>
                <soft_cfm>0</soft_cfm>
                <soft_erp>0.2</soft_erp>
                <kp>1e+13</kp>
                <kd>1</kd>
                <max_vel>0.01</max_vel>
                <min_depth>0</min_depth>
              </ode>
              <bullet>
                <split_impulse>1</split_impulse>
                <split_impulse_penetration_threshold>-0.01</split_impulse_penetration_threshold>
                <soft_cfm>0</soft_cfm>
                <soft_erp>0.2</soft_erp>
                <kp>1e+13</kp>
                <kd>1</kd>
              </bullet>
            </contact>
          </surface>
        </collision>
      </link>
      <static>0</static>
      <allow_auto_disable>1</allow_auto_disable>
      <pose>-8.53457 1.08813 0.103567 -8e-06 1e-05 -1.1e-05</pose>
    </model>
  </world>
</sdf>
